Workbook

Sheet GLOBAL
H1: JUNTA LOCAL DE CONCILIACIÓN Y ARBITRAJE
E2: PROGRAMA PARA LA CONCLUSIÓN DE DE LOS ASUNTOS EN TRAMITE Y EJECUCIÓN DE LAUDOS EN LAS JUNTAS ESPECIALES DE LA LOCAL DE CONCILIACIÓN Y ARBITRAJE
A4: RESPONSABLE | C4: LIC. PATRICIA VELASCO VELAZQUEZ
A5: ÁREA | C5: PRESIDENCIA | I5: ESTADO | K5: ARCHIVO
A6: EJERCICIO | C6: 2026 | I6: =LOOKUP(K5,B8:AA9,B22:AB22) -> #N/A
A7: PERIODO | C7: ENERO-DICIEMBRE
A8: MES | B8: DEMANDAS RADICADAS | E8: LAUDOS | I8: RESOLUCIONES INTERLOCUTORIAS | J8: ACUERDOS | M8: CONVENIOS | N8: AUDIENCIAS | Q8: AUDIENCIAS AREA COLECTIVA | R8: Remates e incidentales | S8: DESISTIMIENTO, CADUCIDAD E INCOMPETENCIA | T8: NOTIFICACIONES | V8: EXHORTOS | W8: AMPAROS | Y8: OFICIOS | Z8: ARCHIVO | AA8: DESPACHOS DE EJECUCIÓN | AB8: TOTAL ASUNTOS POR MES
B9: Ordinarias | C9: Especiales | D9: Para procesales | E9: Condenatorios | F9: Absolutorios | G9: Mixtos | H9: COLECTIVOS | I9: RESOLUCIONES INTERLOCUTORIAS | J9: Junta | K9: Presidencia /tercerias | L9: Colectivos | M9: (cumplimentados) | N9: C,D Y E | O9: ofrecimiento | P9: desahogo de pruebas | T9: EJECUCIONES Y DILIGENCIAS EMBARGOS | U9: ACTUARIOS | W9: Directo | X9: Indirecto
A10: ENERO | B10: =SUM('JUNTA 1'!B10+'JUNTA 2'!B10+'JUNTA 3'!B10+'JUNTA 4'!B10+'JUNTA 5'!B10+'JUNTA 6'!B10+'JUNTA 7'!B10+'JUNTA 8'!B10) -> 0 | C10: =SUM('JUNTA 1'!C10+'JUNTA 2'!C10+'JUNTA 3'!C10+'JUNTA 4'!C10+'JUNTA 5'!C10+'JUNTA 6'!C10+'JUNTA 7'!C10+'JUNTA 8'!C10) -> 0 | D10: =SUM('JUNTA 1'!D10+'JUNTA 2'!D10+'JUNTA 3'!D10+'JUNTA 4'!D10+'JUNTA 5'!D10+'JUNTA 6'!D10+'JUNTA 7'!D10+'JUNTA 8'!D10) -> 0 | E10: =SUM('JUNTA 1'!E10+'JUNTA 2'!E10+'JUNTA 3'!E10+'JUNTA 4'!E10+'JUNTA 5'!E10+'JUNTA 6'!E10+'JUNTA 7'!E10+'JUNTA 8'!E10) -> 15 | F10: =SUM('JUNTA 1'!F10+'JUNTA 2'!F10+'JUNTA 3'!F10+'JUNTA 4'!F10+'JUNTA 5'!F10+'JUNTA 6'!F10+'JUNTA 7'!F10+'JUNTA 8'!F10) -> 10 | G10: =SUM('JUNTA 1'!G10+'JUNTA 2'!G10+'JUNTA 3'!G10+'JUNTA 4'!G10+'JUNTA 5'!G10+'JUNTA 6'!G10+'JUNTA 7'!G10+'JUNTA 8'!G10) -> 0 | H10: ='AREA COLECTIVA Y E.H'!F9 -> 0 | I10: ='JUNTA 1'!O10+'JUNTA 2'!O10+'JUNTA 3'!O10+'JUNTA 4'!O10+'JUNTA 5'!O10+'JUNTA 6'!O10+'JUNTA 7'!O10+'JUNTA 8'!O10+'AREA COLECTIVA Y E.H'!P9 -> 2 | J10: =SUM('JUNTA 1'!H10+'JUNTA 2'!H10+'JUNTA 3'!H10+'JUNTA 4'!H10+'JUNTA 5'!H10+'JUNTA 6'!H10+'JUNTA 7'!H10+'JUNTA 8'!H10) -> 561 | K10: =SUM('JUNTA 1'!I10+'JUNTA 2'!I10+'JUNTA 3'!I10+'JUNTA 4'!I10+'JUNTA 5'!I10+'JUNTA 6'!I10+'JUNTA 7'!I10+'JUNTA 8'!I10) -> 213 | L10: ='AREA COLECTIVA Y E.H'!N9 -> 0 | M10: ='JUNTA 1'!J10+'JUNTA 2'!J10+'JUNTA 3'!J10+'JUNTA 4'!J10+'JUNTA 5'!J10+'JUNTA 6'!J10+'JUNTA 7'!J10+'JUNTA 8'!J10+'AREA COLECTIVA Y E.H'!E9+'AREA COLECTIVA Y E.H'!C9 -> 6 | N10: =SUM('JUNTA 1'!K10+'JUNTA 2'!K10+'JUNTA 3'!K10+'JUNTA 4'!K10+'JUNTA 5'!K10+'JUNTA 6'!K10+'JUNTA 7'!K10+'JUNTA 8'!K10) -> 219 | O10: =SUM('JUNTA 1'!L10+'JUNTA 2'!L10+'JUNTA 3'!L10+'JUNTA 4'!L10+'JUNTA 5'!L10+'JUNTA 6'!L10+'JUNTA 7'!L10+'JUNTA 8'!L10) -> 41 | P10: =SUM('JUNTA 1'!M10+'JUNTA 2'!M10+'JUNTA 3'!M10+'JUNTA 4'!M10+'JUNTA 5'!M10+'JUNTA 6'!M10+'JUNTA 7'!M10+'JUNTA 8'!M10) -> 77 | Q10: ='AREA COLECTIVA Y E.H'!D9 -> 0 | R10: ='JUNTA 1'!N10+'JUNTA 2'!N10+'JUNTA 3'!N10+'JUNTA 4'!N10+'JUNTA 5'!N10+'JUNTA 6'!N10+'JUNTA 7'!N10+'JUNTA 8'!N10+'AREA COLECTIVA Y E.H'!H9 -> 4 | S10: ='JUNTA 1'!P10+'JUNTA 2'!P10+'JUNTA 3'!P10+'JUNTA 4'!P10+'JUNTA 5'!P10+'JUNTA 6'!P10+'JUNTA 7'!P10+'JUNTA 8'!P10+'AREA COLECTIVA Y E.H'!R9 -> 24 | T10: ='JUNTA 1'!Q10+'JUNTA 2'!Q10+'JUNTA 3'!Q10+'JUNTA 4'!Q10+'JUNTA 5'!Q10+'JUNTA 6'!Q10+'JUNTA 7'!Q10+'JUNTA 8'!Q10 -> 11 | U10: ='JUNTA 1'!R10+'JUNTA 2'!R10+'JUNTA 3'!R10+'JUNTA 4'!R10+'JUNTA 5'!R10+'JUNTA 6'!R10+'JUNTA 7'!R10+'JUNTA 8'!R10+'AREA COLECTIVA Y E.H'!I9 -> 1006 | V10: ='JUNTA 1'!S10+'JUNTA 2'!S10+'JUNTA 3'!S10+'JUNTA 4'!S10+'JUNTA 5'!S10+'JUNTA 6'!S10+'JUNTA 7'!S10+'JUNTA 8'!S10+'AREA COLECTIVA Y E.H'!U9 -> 16 | W10: ='JUNTA 1'!T10+'JUNTA 2'!T10+'JUNTA 3'!T10+'JUNTA 4'!T10+'JUNTA 5'!T10+'JUNTA 6'!T10+'JUNTA 7'!T10+'JUNTA 8'!T10 -> 2 | X10: ='JUNTA 1'!U10+'JUNTA 2'!U10+'JUNTA 3'!U10+'JUNTA 4'!U10+'JUNTA 5'!U10+'JUNTA 6'!U10+'JUNTA 7'!U10+'JUNTA 8'!U10 -> 3 | Y10: ='JUNTA 1'!V10+'JUNTA 2'!V10+'JUNTA 3'!V10+'JUNTA 4'!V10+'JUNTA 5'!V10+'JUNTA 6'!V10+'JUNTA 7'!V10+'JUNTA 8'!V10+'AREA COLECTIVA Y E.H'!Q9 -> 220 | Z10: ='JUNTA 1'!W10+'JUNTA 2'!W10+'JUNTA 3'!W10+'JUNTA 4'!W10+'JUNTA 5'!W10+'JUNTA 6'!W10+'JUNTA 7'!W10+'JUNTA 8'!W10+'AREA COLECTIVA Y E.H'!T9 -> 107 | AA10: ='JUNTA 1'!X10+'JUNTA 2'!X10+'JUNTA 3'!X10+'JUNTA 4'!X10+'JUNTA 5'!X10+'JUNTA 6'!X10+'JUNTA 7'!X10+'JUNTA 8'!X10 -> 23 | AB10: =SUM(B10:AA10) -> 2560
A11: FEBRERO | B11: =SUM('JUNTA 1'!B11+'JUNTA 2'!B11+'JUNTA 3'!B11+'JUNTA 4'!B11+'JUNTA 5'!B11+'JUNTA 6'!B11+'JUNTA 7'!B11+'JUNTA 8'!B11) -> 0 | C11: =SUM('JUNTA 1'!C11+'JUNTA 2'!C11+'JUNTA 3'!C11+'JUNTA 4'!C11+'JUNTA 5'!C11+'JUNTA 6'!C11+'JUNTA 7'!C11+'JUNTA 8'!C11) -> 0 | D11: =SUM('JUNTA 1'!D11+'JUNTA 2'!D11+'JUNTA 3'!D11+'JUNTA 4'!D11+'JUNTA 5'!D11+'JUNTA 6'!D11+'JUNTA 7'!D11+'JUNTA 8'!D11) -> 0 | E11: =SUM('JUNTA 1'!E11+'JUNTA 2'!E11+'JUNTA 3'!E11+'JUNTA 4'!E11+'JUNTA 5'!E11+'JUNTA 6'!E11+'JUNTA 7'!E11+'JUNTA 8'!E11) -> 45 | F11: =SUM('JUNTA 1'!F11+'JUNTA 2'!F11+'JUNTA 3'!F11+'JUNTA 4'!F11+'JUNTA 5'!F11+'JUNTA 6'!F11+'JUNTA 7'!F11+'JUNTA 8'!F11) -> 23 | G11: =SUM('JUNTA 1'!G11+'JUNTA 2'!G11+'JUNTA 3'!G11+'JUNTA 4'!G11+'JUNTA 5'!G11+'JUNTA 6'!G11+'JUNTA 7'!G11+'JUNTA 8'!G11) -> 34 | H11: ='AREA COLECTIVA Y E.H'!F10 -> 0 | I11: ='JUNTA 1'!O11+'JUNTA 2'!O11+'JUNTA 3'!O11+'JUNTA 4'!O11+'JUNTA 5'!O11+'JUNTA 6'!O11+'JUNTA 7'!O11+'JUNTA 8'!O11+'AREA COLECTIVA Y E.H'!P10 -> 15 | J11: =SUM('JUNTA 1'!H11+'JUNTA 2'!H11+'JUNTA 3'!H11+'JUNTA 4'!H11+'JUNTA 5'!H11+'JUNTA 6'!H11+'JUNTA 7'!H11+'JUNTA 8'!H11) -> 1366 | K11: =SUM('JUNTA 1'!I11+'JUNTA 2'!I11+'JUNTA 3'!I11+'JUNTA 4'!I11+'JUNTA 5'!I11+'JUNTA 6'!I11+'JUNTA 7'!I11+'JUNTA 8'!I11) -> 558 | L11: ='AREA COLECTIVA Y E.H'!N10 -> 11 | M11: ='JUNTA 1'!J11+'JUNTA 2'!J11+'JUNTA 3'!J11+'JUNTA 4'!J11+'JUNTA 5'!J11+'JUNTA 6'!J11+'JUNTA 7'!J11+'JUNTA 8'!J11+'AREA COLECTIVA Y E.H'!E10+'AREA COLECTIVA Y E.H'!C10 -> 21 | N11: =SUM('JUNTA 1'!K11+'JUNTA 2'!K11+'JUNTA 3'!K11+'JUNTA 4'!K11+'JUNTA 5'!K11+'JUNTA 6'!K11+'JUNTA 7'!K11+'JUNTA 8'!K11) -> 304 | O11: =SUM('JUNTA 1'!L11+'JUNTA 2'!L11+'JUNTA 3'!L11+'JUNTA 4'!L11+'JUNTA 5'!L11+'JUNTA 6'!L11+'JUNTA 7'!L11+'JUNTA 8'!L11) -> 58 | P11: =SUM('JUNTA 1'!M11+'JUNTA 2'!M11+'JUNTA 3'!M11+'JUNTA 4'!M11+'JUNTA 5'!M11+'JUNTA 6'!M11+'JUNTA 7'!M11+'JUNTA 8'!M11) -> 108 | Q11: ='AREA COLECTIVA Y E.H'!D10 -> 1 | R11: ='JUNTA 1'!N11+'JUNTA 2'!N11+'JUNTA 3'!N11+'JUNTA 4'!N11+'JUNTA 5'!N11+'JUNTA 6'!N11+'JUNTA 7'!N11+'JUNTA 8'!N11+'AREA COLECTIVA Y E.H'!H10 -> 11 | S11: ='JUNTA 1'!P11+'JUNTA 2'!P11+'JUNTA 3'!P11+'JUNTA 4'!P11+'JUNTA 5'!P11+'JUNTA 6'!P11+'JUNTA 7'!P11+'JUNTA 8'!P11+'AREA COLECTIVA Y E.H'!R10 -> 249 | T11: ='JUNTA 1'!Q11+'JUNTA 2'!Q11+'JUNTA 3'!Q11+'JUNTA 4'!Q11+'JUNTA 5'!Q11+'JUNTA 6'!Q11+'JUNTA 7'!Q11+'JUNTA 8'!Q11 -> 27 | U11: ='JUNTA 1'!R11+'JUNTA 2'!R11+'JUNTA 3'!R11+'JUNTA 4'!R11+'JUNTA 5'!R11+'JUNTA 6'!R11+'JUNTA 7'!R11+'JUNTA 8'!R11+'AREA COLECTIVA Y E.H'!I10 -> 1968 | V11: ='JUNTA 1'!S11+'JUNTA 2'!S11+'JUNTA 3'!S11+'JUNTA 4'!S11+'JUNTA 5'!S11+'JUNTA 6'!S11+'JUNTA 7'!S11+'JUNTA 8'!S11+'AREA COLECTIVA Y E.H'!U10 -> 42 | W11: ='JUNTA 1'!T11+'JUNTA 2'!T11+'JUNTA 3'!T11+'JUNTA 4'!T11+'JUNTA 5'!T11+'JUNTA 6'!T11+'JUNTA 7'!T11+'JUNTA 8'!T11 -> 33 | X11: ='JUNTA 1'!U11+'JUNTA 2'!U11+'JUNTA 3'!U11+'JUNTA 4'!U11+'JUNTA 5'!U11+'JUNTA 6'!U11+'JUNTA 7'!U11+'JUNTA 8'!U11 -> 43 | Y11: ='JUNTA 1'!V11+'JUNTA 2'!V11+'JUNTA 3'!V11+'JUNTA 4'!V11+'JUNTA 5'!V11+'JUNTA 6'!V11+'JUNTA 7'!V11+'JUNTA 8'!V11+'AREA COLECTIVA Y E.H'!Q10 -> 454 | Z11: ='JUNTA 1'!W11+'JUNTA 2'!W11+'JUNTA 3'!W11+'JUNTA 4'!W11+'JUNTA 5'!W11+'JUNTA 6'!W11+'JUNTA 7'!W11+'JUNTA 8'!W11+'AREA COLECTIVA Y E.H'!T10 -> 173 | AA11: ='JUNTA 1'!X11+'JUNTA 2'!X11+'JUNTA 3'!X11+'JUNTA 4'!X11+'JUNTA 5'!X11+'JUNTA 6'!X11+'JUNTA 7'!X11+'JUNTA 8'!X11 -> 37 | AB11: =SUM(B11:AA11) -> 5581
A12: MARZO | B12: =SUM('JUNTA 1'!B12+'JUNTA 2'!B12+'JUNTA 3'!B12+'JUNTA 4'!B12+'JUNTA 5'!B12+'JUNTA 6'!B12+'JUNTA 7'!B12+'JUNTA 8'!B12) -> 2 | C12: =SUM('JUNTA 1'!C12+'JUNTA 2'!C12+'JUNTA 3'!C12+'JUNTA 4'!C12+'JUNTA 5'!C12+'JUNTA 6'!C12+'JUNTA 7'!C12+'JUNTA 8'!C12) -> 0 | D12: =SUM('JUNTA 1'!D12+'JUNTA 2'!D12+'JUNTA 3'!D12+'JUNTA 4'!D12+'JUNTA 5'!D12+'JUNTA 6'!D12+'JUNTA 7'!D12+'JUNTA 8'!D12) -> 0 | E12: =SUM('JUNTA 1'!E12+'JUNTA 2'!E12+'JUNTA 3'!E12+'JUNTA 4'!E12+'JUNTA 5'!E12+'JUNTA 6'!E12+'JUNTA 7'!E12+'JUNTA 8'!E12) -> 67 | F12: =SUM('JUNTA 1'!F12+'JUNTA 2'!F12+'JUNTA 3'!F12+'JUNTA 4'!F12+'JUNTA 5'!F12+'JUNTA 6'!F12+'JUNTA 7'!F12+'JUNTA 8'!F12) -> 45 | G12: =SUM('JUNTA 1'!G12+'JUNTA 2'!G12+'JUNTA 3'!G12+'JUNTA 4'!G12+'JUNTA 5'!G12+'JUNTA 6'!G12+'JUNTA 7'!G12+'JUNTA 8'!G12) -> 43 | H12: ='AREA COLECTIVA Y E.H'!F11 -> 4 | I12: ='JUNTA 1'!O12+'JUNTA 2'!O12+'JUNTA 3'!O12+'JUNTA 4'!O12+'JUNTA 5'!O12+'JUNTA 6'!O12+'JUNTA 7'!O12+'JUNTA 8'!O12+'AREA COLECTIVA Y E.H'!P11 -> 16 | J12: =SUM('JUNTA 1'!H12+'JUNTA 2'!H12+'JUNTA 3'!H12+'JUNTA 4'!H12+'JUNTA 5'!H12+'JUNTA 6'!H12+'JUNTA 7'!H12+'JUNTA 8'!H12) -> 1915 | K12: =SUM('JUNTA 1'!I12+'JUNTA 2'!I12+'JUNTA 3'!I12+'JUNTA 4'!I12+'JUNTA 5'!I12+'JUNTA 6'!I12+'JUNTA 7'!I12+'JUNTA 8'!I12) -> 837 | L12: ='AREA COLECTIVA Y E.H'!N11 -> 37 | M12: ='JUNTA 1'!J12+'JUNTA 2'!J12+'JUNTA 3'!J12+'JUNTA 4'!J12+'JUNTA 5'!J12+'JUNTA 6'!J12+'JUNTA 7'!J12+'JUNTA 8'!J12+'AREA COLECTIVA Y E.H'!E11+'AREA COLECTIVA Y E.H'!C11 -> 29 | N12: =SUM('JUNTA 1'!K12+'JUNTA 2'!K12+'JUNTA 3'!K12+'JUNTA 4'!K12+'JUNTA 5'!K12+'JUNTA 6'!K12+'JUNTA 7'!K12+'JUNTA 8'!K12) -> 432 | O12: =SUM('JUNTA 1'!L12+'JUNTA 2'!L12+'JUNTA 3'!L12+'JUNTA 4'!L12+'JUNTA 5'!L12+'JUNTA 6'!L12+'JUNTA 7'!L12+'JUNTA 8'!L12) -> 58 | P12: =SUM('JUNTA 1'!M12+'JUNTA 2'!M12+'JUNTA 3'!M12+'JUNTA 4'!M12+'JUNTA 5'!M12+'JUNTA 6'!M12+'JUNTA 7'!M12+'JUNTA 8'!M12) -> 218 | Q12: ='AREA COLECTIVA Y E.H'!D11 -> 5 | R12: ='JUNTA 1'!N12+'JUNTA 2'!N12+'JUNTA 3'!N12+'JUNTA 4'!N12+'JUNTA 5'!N12+'JUNTA 6'!N12+'JUNTA 7'!N12+'JUNTA 8'!N12+'AREA COLECTIVA Y E.H'!H11 -> 15 | S12: ='JUNTA 1'!P12+'JUNTA 2'!P12+'JUNTA 3'!P12+'JUNTA 4'!P12+'JUNTA 5'!P12+'JUNTA 6'!P12+'JUNTA 7'!P12+'JUNTA 8'!P12+'AREA COLECTIVA Y E.H'!R11 -> 82 | T12: ='JUNTA 1'!Q12+'JUNTA 2'!Q12+'JUNTA 3'!Q12+'JUNTA 4'!Q12+'JUNTA 5'!Q12+'JUNTA 6'!Q12+'JUNTA 7'!Q12+'JUNTA 8'!Q12 -> 64 | U12: ='JUNTA 1'!R12+'JUNTA 2'!R12+'JUNTA 3'!R12+'JUNTA 4'!R12+'JUNTA 5'!R12+'JUNTA 6'!R12+'JUNTA 7'!R12+'JUNTA 8'!R12+'AREA COLECTIVA Y E.H'!I11 -> 2737 | V12: ='JUNTA 1'!S12+'JUNTA 2'!S12+'JUNTA 3'!S12+'JUNTA 4'!S12+'JUNTA 5'!S12+'JUNTA 6'!S12+'JUNTA 7'!S12+'JUNTA 8'!S12+'AREA COLECTIVA Y E.H'!U11 -> 83 | W12: ='JUNTA 1'!T12+'JUNTA 2'!T12+'JUNTA 3'!T12+'JUNTA 4'!T12+'JUNTA 5'!T12+'JUNTA 6'!T12+'JUNTA 7'!T12+'JUNTA 8'!T12 -> 38 | X12: ='JUNTA 1'!U12+'JUNTA 2'!U12+'JUNTA 3'!U12+'JUNTA 4'!U12+'JUNTA 5'!U12+'JUNTA 6'!U12+'JUNTA 7'!U12+'JUNTA 8'!U12 -> 66 | Y12: ='JUNTA 1'!V12+'JUNTA 2'!V12+'JUNTA 3'!V12+'JUNTA 4'!V12+'JUNTA 5'!V12+'JUNTA 6'!V12+'JUNTA 7'!V12+'JUNTA 8'!V12+'AREA COLECTIVA Y E.H'!Q11 -> 1459 | Z12: ='JUNTA 1'!W12+'JUNTA 2'!W12+'JUNTA 3'!W12+'JUNTA 4'!W12+'JUNTA 5'!W12+'JUNTA 6'!W12+'JUNTA 7'!W12+'JUNTA 8'!W12+'AREA COLECTIVA Y E.H'!T11 -> 134 | AA12: ='JUNTA 1'!X12+'JUNTA 2'!X12+'JUNTA 3'!X12+'JUNTA 4'!X12+'JUNTA 5'!X12+'JUNTA 6'!X12+'JUNTA 7'!X12+'JUNTA 8'!X12 -> 78 | AB12: =SUM(B12:AA12) -> 8464
A13: ABRIL | B13: =SUM('JUNTA 1'!B13+'JUNTA 2'!B13+'JUNTA 3'!B13+'JUNTA 4'!B13+'JUNTA 5'!B13+'JUNTA 6'!B13+'JUNTA 7'!B13+'JUNTA 8'!B13) -> 0 | C13: =SUM('JUNTA 1'!C13+'JUNTA 2'!C13+'JUNTA 3'!C13+'JUNTA 4'!C13+'JUNTA 5'!C13+'JUNTA 6'!C13+'JUNTA 7'!C13+'JUNTA 8'!C13) -> 0 | D13: =SUM('JUNTA 1'!D13+'JUNTA 2'!D13+'JUNTA 3'!D13+'JUNTA 4'!D13+'JUNTA 5'!D13+'JUNTA 6'!D13+'JUNTA 7'!D13+'JUNTA 8'!D13) -> 0 | E13: =SUM('JUNTA 1'!E13+'JUNTA 2'!E13+'JUNTA 3'!E13+'JUNTA 4'!E13+'JUNTA 5'!E13+'JUNTA 6'!E13+'JUNTA 7'!E13+'JUNTA 8'!E13) -> 71 | F13: =SUM('JUNTA 1'!F13+'JUNTA 2'!F13+'JUNTA 3'!F13+'JUNTA 4'!F13+'JUNTA 5'!F13+'JUNTA 6'!F13+'JUNTA 7'!F13+'JUNTA 8'!F13) -> 27 | G13: =SUM('JUNTA 1'!G13+'JUNTA 2'!G13+'JUNTA 3'!G13+'JUNTA 4'!G13+'JUNTA 5'!G13+'JUNTA 6'!G13+'JUNTA 7'!G13+'JUNTA 8'!G13) -> 44 | H13: ='AREA COLECTIVA Y E.H'!F12 -> 0 | I13: ='JUNTA 1'!O13+'JUNTA 2'!O13+'JUNTA 3'!O13+'JUNTA 4'!O13+'JUNTA 5'!O13+'JUNTA 6'!O13+'JUNTA 7'!O13+'JUNTA 8'!O13+'AREA COLECTIVA Y E.H'!P12 -> 21 | J13: =SUM('JUNTA 1'!H13+'JUNTA 2'!H13+'JUNTA 3'!H13+'JUNTA 4'!H13+'JUNTA 5'!H13+'JUNTA 6'!H13+'JUNTA 7'!H13+'JUNTA 8'!H13) -> 2056 | K13: =SUM('JUNTA 1'!I13+'JUNTA 2'!I13+'JUNTA 3'!I13+'JUNTA 4'!I13+'JUNTA 5'!I13+'JUNTA 6'!I13+'JUNTA 7'!I13+'JUNTA 8'!I13) -> 1061 | L13: ='AREA COLECTIVA Y E.H'!N12 -> 64 | M13: ='JUNTA 1'!J13+'JUNTA 2'!J13+'JUNTA 3'!J13+'JUNTA 4'!J13+'JUNTA 5'!J13+'JUNTA 6'!J13+'JUNTA 7'!J13+'JUNTA 8'!J13+'AREA COLECTIVA Y E.H'!E12+'AREA COLECTIVA Y E.H'!C12 -> 55 | N13: =SUM('JUNTA 1'!K13+'JUNTA 2'!K13+'JUNTA 3'!K13+'JUNTA 4'!K13+'JUNTA 5'!K13+'JUNTA 6'!K13+'JUNTA 7'!K13+'JUNTA 8'!K13) -> 485 | O13: =SUM('JUNTA 1'!L13+'JUNTA 2'!L13+'JUNTA 3'!L13+'JUNTA 4'!L13+'JUNTA 5'!L13+'JUNTA 6'!L13+'JUNTA 7'!L13+'JUNTA 8'!L13) -> 47 | P13: =SUM('JUNTA 1'!M13+'JUNTA 2'!M13+'JUNTA 3'!M13+'JUNTA 4'!M13+'JUNTA 5'!M13+'JUNTA 6'!M13+'JUNTA 7'!M13+'JUNTA 8'!M13) -> 273 | Q13: ='AREA COLECTIVA Y E.H'!D12 -> 10 | R13: ='JUNTA 1'!N13+'JUNTA 2'!N13+'JUNTA 3'!N13+'JUNTA 4'!N13+'JUNTA 5'!N13+'JUNTA 6'!N13+'JUNTA 7'!N13+'JUNTA 8'!N13+'AREA COLECTIVA Y E.H'!H12 -> 40 | S13: ='JUNTA 1'!P13+'JUNTA 2'!P13+'JUNTA 3'!P13+'JUNTA 4'!P13+'JUNTA 5'!P13+'JUNTA 6'!P13+'JUNTA 7'!P13+'JUNTA 8'!P13+'AREA COLECTIVA Y E.H'!R12 -> 73 | T13: ='JUNTA 1'!Q13+'JUNTA 2'!Q13+'JUNTA 3'!Q13+'JUNTA 4'!Q13+'JUNTA 5'!Q13+'JUNTA 6'!Q13+'JUNTA 7'!Q13+'JUNTA 8'!Q13 -> 68 | U13: ='JUNTA 1'!R13+'JUNTA 2'!R13+'JUNTA 3'!R13+'JUNTA 4'!R13+'JUNTA 5'!R13+'JUNTA 6'!R13+'JUNTA 7'!R13+'JUNTA 8'!R13+'AREA COLECTIVA Y E.H'!I12 -> 3927 | V13: ='JUNTA 1'!S13+'JUNTA 2'!S13+'JUNTA 3'!S13+'JUNTA 4'!S13+'JUNTA 5'!S13+'JUNTA 6'!S13+'JUNTA 7'!S13+'JUNTA 8'!S13+'AREA COLECTIVA Y E.H'!U12 -> 55 | W13: ='JUNTA 1'!T13+'JUNTA 2'!T13+'JUNTA 3'!T13+'JUNTA 4'!T13+'JUNTA 5'!T13+'JUNTA 6'!T13+'JUNTA 7'!T13+'JUNTA 8'!T13 -> 44 | X13: ='JUNTA 1'!U13+'JUNTA 2'!U13+'JUNTA 3'!U13+'JUNTA 4'!U13+'JUNTA 5'!U13+'JUNTA 6'!U13+'JUNTA 7'!U13+'JUNTA 8'!U13 -> 89 | Y13: ='JUNTA 1'!V13+'JUNTA 2'!V13+'JUNTA 3'!V13+'JUNTA 4'!V13+'JUNTA 5'!V13+'JUNTA 6'!V13+'JUNTA 7'!V13+'JUNTA 8'!V13+'AREA COLECTIVA Y E.H'!Q12 -> 1505 | Z13: ='JUNTA 1'!W13+'JUNTA 2'!W13+'JUNTA 3'!W13+'JUNTA 4'!W13+'JUNTA 5'!W13+'JUNTA 6'!W13+'JUNTA 7'!W13+'JUNTA 8'!W13+'AREA COLECTIVA Y E.H'!T12 -> 377 | AA13: ='JUNTA 1'!X13+'JUNTA 2'!X13+'JUNTA 3'!X13+'JUNTA 4'!X13+'JUNTA 5'!X13+'JUNTA 6'!X13+'JUNTA 7'!X13+'JUNTA 8'!X13 -> 79 | AB13: =SUM(B13:AA13) -> 10471
A14: MAYO | B14: =SUM('JUNTA 1'!B14+'JUNTA 2'!B14+'JUNTA 3'!B14+'JUNTA 4'!B14+'JUNTA 5'!B14+'JUNTA 6'!B14+'JUNTA 7'!B14+'JUNTA 8'!B14) -> 0 | C14: =SUM('JUNTA 1'!C14+'JUNTA 2'!C14+'JUNTA 3'!C14+'JUNTA 4'!C14+'JUNTA 5'!C14+'JUNTA 6'!C14+'JUNTA 7'!C14+'JUNTA 8'!C14) -> 0 | D14: =SUM('JUNTA 1'!D14+'JUNTA 2'!D14+'JUNTA 3'!D14+'JUNTA 4'!D14+'JUNTA 5'!D14+'JUNTA 6'!D14+'JUNTA 7'!D14+'JUNTA 8'!D14) -> 0 | E14: =SUM('JUNTA 1'!E14+'JUNTA 2'!E14+'JUNTA 3'!E14+'JUNTA 4'!E14+'JUNTA 5'!E14+'JUNTA 6'!E14+'JUNTA 7'!E14+'JUNTA 8'!E14) -> 0 | F14: =SUM('JUNTA 1'!F14+'JUNTA 2'!F14+'JUNTA 3'!F14+'JUNTA 4'!F14+'JUNTA 5'!F14+'JUNTA 6'!F14+'JUNTA 7'!F14+'JUNTA 8'!F14) -> 0 | G14: =SUM('JUNTA 1'!G14+'JUNTA 2'!G14+'JUNTA 3'!G14+'JUNTA 4'!G14+'JUNTA 5'!G14+'JUNTA 6'!G14+'JUNTA 7'!G14+'JUNTA 8'!G14) -> 0 | H14: ='AREA COLECTIVA Y E.H'!F13 -> 0 | I14: ='JUNTA 1'!O14+'JUNTA 2'!O14+'JUNTA 3'!O14+'JUNTA 4'!O14+'JUNTA 5'!O14+'JUNTA 6'!O14+'JUNTA 7'!O14+'JUNTA 8'!O14+'AREA COLECTIVA Y E.H'!P13 -> 0 | J14: =SUM('JUNTA 1'!H14+'JUNTA 2'!H14+'JUNTA 3'!H14+'JUNTA 4'!H14+'JUNTA 5'!H14+'JUNTA 6'!H14+'JUNTA 7'!H14+'JUNTA 8'!H14) -> 0 | K14: =SUM('JUNTA 1'!I14+'JUNTA 2'!I14+'JUNTA 3'!I14+'JUNTA 4'!I14+'JUNTA 5'!I14+'JUNTA 6'!I14+'JUNTA 7'!I14+'JUNTA 8'!I14) -> 0 | L14: ='AREA COLECTIVA Y E.H'!N13 -> 0 | M14: ='JUNTA 1'!J14+'JUNTA 2'!J14+'JUNTA 3'!J14+'JUNTA 4'!J14+'JUNTA 5'!J14+'JUNTA 6'!J14+'JUNTA 7'!J14+'JUNTA 8'!J14+'AREA COLECTIVA Y E.H'!E13+'AREA COLECTIVA Y E.H'!C13 -> 0 | N14: =SUM('JUNTA 1'!K14+'JUNTA 2'!K14+'JUNTA 3'!K14+'JUNTA 4'!K14+'JUNTA 5'!K14+'JUNTA 6'!K14+'JUNTA 7'!K14+'JUNTA 8'!K14) -> 0 | O14: =SUM('JUNTA 1'!L14+'JUNTA 2'!L14+'JUNTA 3'!L14+'JUNTA 4'!L14+'JUNTA 5'!L14+'JUNTA 6'!L14+'JUNTA 7'!L14+'JUNTA 8'!L14) -> 0 | P14: =SUM('JUNTA 1'!M14+'JUNTA 2'!M14+'JUNTA 3'!M14+'JUNTA 4'!M14+'JUNTA 5'!M14+'JUNTA 6'!M14+'JUNTA 7'!M14+'JUNTA 8'!M14) -> 0 | Q14: ='AREA COLECTIVA Y E.H'!D13 -> 0 | R14: ='JUNTA 1'!N14+'JUNTA 2'!N14+'JUNTA 3'!N14+'JUNTA 4'!N14+'JUNTA 5'!N14+'JUNTA 6'!N14+'JUNTA 7'!N14+'JUNTA 8'!N14+'AREA COLECTIVA Y E.H'!H13 -> 0 | S14: ='JUNTA 1'!P14+'JUNTA 2'!P14+'JUNTA 3'!P14+'JUNTA 4'!P14+'JUNTA 5'!P14+'JUNTA 6'!P14+'JUNTA 7'!P14+'JUNTA 8'!P14+'AREA COLECTIVA Y E.H'!R13 -> 0 | T14: ='JUNTA 1'!Q14+'JUNTA 2'!Q14+'JUNTA 3'!Q14+'JUNTA 4'!Q14+'JUNTA 5'!Q14+'JUNTA 6'!Q14+'JUNTA 7'!Q14+'JUNTA 8'!Q14 -> 0 | U14: ='JUNTA 1'!R14+'JUNTA 2'!R14+'JUNTA 3'!R14+'JUNTA 4'!R14+'JUNTA 5'!R14+'JUNTA 6'!R14+'JUNTA 7'!R14+'JUNTA 8'!R14+'AREA COLECTIVA Y E.H'!I13 -> 0 | V14: ='JUNTA 1'!S14+'JUNTA 2'!S14+'JUNTA 3'!S14+'JUNTA 4'!S14+'JUNTA 5'!S14+'JUNTA 6'!S14+'JUNTA 7'!S14+'JUNTA 8'!S14+'AREA COLECTIVA Y E.H'!U13 -> 0 | W14: ='JUNTA 1'!T14+'JUNTA 2'!T14+'JUNTA 3'!T14+'JUNTA 4'!T14+'JUNTA 5'!T14+'JUNTA 6'!T14+'JUNTA 7'!T14+'JUNTA 8'!T14 -> 0 | X14: ='JUNTA 1'!U14+'JUNTA 2'!U14+'JUNTA 3'!U14+'JUNTA 4'!U14+'JUNTA 5'!U14+'JUNTA 6'!U14+'JUNTA 7'!U14+'JUNTA 8'!U14 -> 0 | Y14: ='JUNTA 1'!V14+'JUNTA 2'!V14+'JUNTA 3'!V14+'JUNTA 4'!V14+'JUNTA 5'!V14+'JUNTA 6'!V14+'JUNTA 7'!V14+'JUNTA 8'!V14+'AREA COLECTIVA Y E.H'!Q13 -> 0 | Z14: ='JUNTA 1'!W14+'JUNTA 2'!W14+'JUNTA 3'!W14+'JUNTA 4'!W14+'JUNTA 5'!W14+'JUNTA 6'!W14+'JUNTA 7'!W14+'JUNTA 8'!W14+'AREA COLECTIVA Y E.H'!T13 -> 0 | AA14: ='JUNTA 1'!X14+'JUNTA 2'!X14+'JUNTA 3'!X14+'JUNTA 4'!X14+'JUNTA 5'!X14+'JUNTA 6'!X14+'JUNTA 7'!X14+'JUNTA 8'!X14 -> 0 | AB14: =SUM(B14:AA14) -> 0
A15: JUNIO | B15: =SUM('JUNTA 1'!B15+'JUNTA 2'!B15+'JUNTA 3'!B15+'JUNTA 4'!B15+'JUNTA 5'!B15+'JUNTA 6'!B15+'JUNTA 7'!B15+'JUNTA 8'!B15) -> 0 | C15: =SUM('JUNTA 1'!C15+'JUNTA 2'!C15+'JUNTA 3'!C15+'JUNTA 4'!C15+'JUNTA 5'!C15+'JUNTA 6'!C15+'JUNTA 7'!C15+'JUNTA 8'!C15) -> 0 | D15: =SUM('JUNTA 1'!D15+'JUNTA 2'!D15+'JUNTA 3'!D15+'JUNTA 4'!D15+'JUNTA 5'!D15+'JUNTA 6'!D15+'JUNTA 7'!D15+'JUNTA 8'!D15) -> 0 | E15: =SUM('JUNTA 1'!E15+'JUNTA 2'!E15+'JUNTA 3'!E15+'JUNTA 4'!E15+'JUNTA 5'!E15+'JUNTA 6'!E15+'JUNTA 7'!E15+'JUNTA 8'!E15) -> 0 | F15: =SUM('JUNTA 1'!F15+'JUNTA 2'!F15+'JUNTA 3'!F15+'JUNTA 4'!F15+'JUNTA 5'!F15+'JUNTA 6'!F15+'JUNTA 7'!F15+'JUNTA 8'!F15) -> 0 | G15: =SUM('JUNTA 1'!G15+'JUNTA 2'!G15+'JUNTA 3'!G15+'JUNTA 4'!G15+'JUNTA 5'!G15+'JUNTA 6'!G15+'JUNTA 7'!G15+'JUNTA 8'!G15) -> 0 | H15: ='AREA COLECTIVA Y E.H'!F14 -> 0 | I15: ='JUNTA 1'!O15+'JUNTA 2'!O15+'JUNTA 3'!O15+'JUNTA 4'!O15+'JUNTA 5'!O15+'JUNTA 6'!O15+'JUNTA 7'!O15+'JUNTA 8'!O15+'AREA COLECTIVA Y E.H'!P14 -> 0 | J15: =SUM('JUNTA 1'!H15+'JUNTA 2'!H15+'JUNTA 3'!H15+'JUNTA 4'!H15+'JUNTA 5'!H15+'JUNTA 6'!H15+'JUNTA 7'!H15+'JUNTA 8'!H15) -> 0 | K15: =SUM('JUNTA 1'!I15+'JUNTA 2'!I15+'JUNTA 3'!I15+'JUNTA 4'!I15+'JUNTA 5'!I15+'JUNTA 6'!I15+'JUNTA 7'!I15+'JUNTA 8'!I15) -> 0 | L15: ='AREA COLECTIVA Y E.H'!N14 -> 0 | M15: ='JUNTA 1'!J15+'JUNTA 2'!J15+'JUNTA 3'!J15+'JUNTA 4'!J15+'JUNTA 5'!J15+'JUNTA 6'!J15+'JUNTA 7'!J15+'JUNTA 8'!J15+'AREA COLECTIVA Y E.H'!E14+'AREA COLECTIVA Y E.H'!C14 -> 0 | N15: =SUM('JUNTA 1'!K15+'JUNTA 2'!K15+'JUNTA 3'!K15+'JUNTA 4'!K15+'JUNTA 5'!K15+'JUNTA 6'!K15+'JUNTA 7'!K15+'JUNTA 8'!K15) -> 0 | O15: =SUM('JUNTA 1'!L15+'JUNTA 2'!L15+'JUNTA 3'!L15+'JUNTA 4'!L15+'JUNTA 5'!L15+'JUNTA 6'!L15+'JUNTA 7'!L15+'JUNTA 8'!L15) -> 0 | P15: =SUM('JUNTA 1'!M15+'JUNTA 2'!M15+'JUNTA 3'!M15+'JUNTA 4'!M15+'JUNTA 5'!M15+'JUNTA 6'!M15+'JUNTA 7'!M15+'JUNTA 8'!M15) -> 0 | Q15: ='AREA COLECTIVA Y E.H'!D14 -> 0 | R15: ='JUNTA 1'!N15+'JUNTA 2'!N15+'JUNTA 3'!N15+'JUNTA 4'!N15+'JUNTA 5'!N15+'JUNTA 6'!N15+'JUNTA 7'!N15+'JUNTA 8'!N15+'AREA COLECTIVA Y E.H'!H14 -> 0 | S15: ='JUNTA 1'!P15+'JUNTA 2'!P15+'JUNTA 3'!P15+'JUNTA 4'!P15+'JUNTA 5'!P15+'JUNTA 6'!P15+'JUNTA 7'!P15+'JUNTA 8'!P15+'AREA COLECTIVA Y E.H'!R14 -> 0 | T15: ='JUNTA 1'!Q15+'JUNTA 2'!Q15+'JUNTA 3'!Q15+'JUNTA 4'!Q15+'JUNTA 5'!Q15+'JUNTA 6'!Q15+'JUNTA 7'!Q15+'JUNTA 8'!Q15 -> 0 | U15: ='JUNTA 1'!R15+'JUNTA 2'!R15+'JUNTA 3'!R15+'JUNTA 4'!R15+'JUNTA 5'!R15+'JUNTA 6'!R15+'JUNTA 7'!R15+'JUNTA 8'!R15+'AREA COLECTIVA Y E.H'!I15 -> 0 | V15: ='JUNTA 1'!S15+'JUNTA 2'!S15+'JUNTA 3'!S15+'JUNTA 4'!S15+'JUNTA 5'!S15+'JUNTA 6'!S15+'JUNTA 7'!S15+'JUNTA 8'!S15+'AREA COLECTIVA Y E.H'!U14 -> 0 | W15: ='JUNTA 1'!T15+'JUNTA 2'!T15+'JUNTA 3'!T15+'JUNTA 4'!T15+'JUNTA 5'!T15+'JUNTA 6'!T15+'JUNTA 7'!T15+'JUNTA 8'!T15 -> 0 | X15: ='JUNTA 1'!U15+'JUNTA 2'!U15+'JUNTA 3'!U15+'JUNTA 4'!U15+'JUNTA 5'!U15+'JUNTA 6'!U15+'JUNTA 7'!U15+'JUNTA 8'!U15 -> 0 | Y15: ='JUNTA 1'!V15+'JUNTA 2'!V15+'JUNTA 3'!V15+'JUNTA 4'!V15+'JUNTA 5'!V15+'JUNTA 6'!V15+'JUNTA 7'!V15+'JUNTA 8'!V15+'AREA COLECTIVA Y E.H'!Q14 -> 0 | Z15: ='JUNTA 1'!W15+'JUNTA 2'!W15+'JUNTA 3'!W15+'JUNTA 4'!W15+'JUNTA 5'!W15+'JUNTA 6'!W15+'JUNTA 7'!W15+'JUNTA 8'!W15+'AREA COLECTIVA Y E.H'!T14 -> 0 | AA15: ='JUNTA 1'!X15+'JUNTA 2'!X15+'JUNTA 3'!X15+'JUNTA 4'!X15+'JUNTA 5'!X15+'JUNTA 6'!X15+'JUNTA 7'!X15+'JUNTA 8'!X15 -> 0 | AB15: =SUM(B15:AA15) -> 0
A16: JULIO | B16: =SUM('JUNTA 1'!B16+'JUNTA 2'!B16+'JUNTA 3'!B16+'JUNTA 4'!B16+'JUNTA 5'!B16+'JUNTA 6'!B16+'JUNTA 7'!B16+'JUNTA 8'!B16) -> 0 | C16: =SUM('JUNTA 1'!C16+'JUNTA 2'!C16+'JUNTA 3'!C16+'JUNTA 4'!C16+'JUNTA 5'!C16+'JUNTA 6'!C16+'JUNTA 7'!C16+'JUNTA 8'!C16) -> 0 | D16: =SUM('JUNTA 1'!D16+'JUNTA 2'!D16+'JUNTA 3'!D16+'JUNTA 4'!D16+'JUNTA 5'!D16+'JUNTA 6'!D16+'JUNTA 7'!D16+'JUNTA 8'!D16) -> 0 | E16: =SUM('JUNTA 1'!E16+'JUNTA 2'!E16+'JUNTA 3'!E16+'JUNTA 4'!E16+'JUNTA 5'!E16+'JUNTA 6'!E16+'JUNTA 7'!E16+'JUNTA 8'!E16) -> 0 | F16: =SUM('JUNTA 1'!F16+'JUNTA 2'!F16+'JUNTA 3'!F16+'JUNTA 4'!F16+'JUNTA 5'!F16+'JUNTA 6'!F16+'JUNTA 7'!F16+'JUNTA 8'!F16) -> 0 | G16: =SUM('JUNTA 1'!G16+'JUNTA 2'!G16+'JUNTA 3'!G16+'JUNTA 4'!G16+'JUNTA 5'!G16+'JUNTA 6'!G16+'JUNTA 7'!G16+'JUNTA 8'!G16) -> 0 | H16: ='AREA COLECTIVA Y E.H'!F15 -> 0 | I16: ='JUNTA 1'!O16+'JUNTA 2'!O16+'JUNTA 3'!O16+'JUNTA 4'!O16+'JUNTA 5'!O16+'JUNTA 6'!O16+'JUNTA 7'!O16+'JUNTA 8'!O16+'AREA COLECTIVA Y E.H'!P15 -> 0 | J16: =SUM('JUNTA 1'!H16+'JUNTA 2'!H16+'JUNTA 3'!H16+'JUNTA 4'!H16+'JUNTA 5'!H16+'JUNTA 6'!H16+'JUNTA 7'!H16+'JUNTA 8'!H16) -> 0 | K16: =SUM('JUNTA 1'!I16+'JUNTA 2'!I16+'JUNTA 3'!I16+'JUNTA 4'!I16+'JUNTA 5'!I16+'JUNTA 6'!I16+'JUNTA 7'!I16+'JUNTA 8'!I16) -> 0 | L16: ='AREA COLECTIVA Y E.H'!N15 -> 0 | M16: =SUM('JUNTA 1'!J16+'JUNTA 2'!J16+'JUNTA 3'!J16+'JUNTA 4'!J16+'JUNTA 5'!J16+'JUNTA 6'!J16+'JUNTA 7'!J16+'JUNTA 8'!J16+'AREA COLECTIVA Y E.H'!E15+'AREA COLECTIVA Y E.H'!C15) -> 0 | N16: =SUM('JUNTA 1'!K16+'JUNTA 2'!K16+'JUNTA 3'!K16+'JUNTA 4'!K16+'JUNTA 5'!K16+'JUNTA 6'!K16+'JUNTA 7'!K16+'JUNTA 8'!K16) -> 0 | O16: =SUM('JUNTA 1'!L16+'JUNTA 2'!L16+'JUNTA 3'!L16+'JUNTA 4'!L16+'JUNTA 5'!L16+'JUNTA 6'!L16+'JUNTA 7'!L16+'JUNTA 8'!L16) -> 0 | P16: =SUM('JUNTA 1'!M16+'JUNTA 2'!M16+'JUNTA 3'!M16+'JUNTA 4'!M16+'JUNTA 5'!M16+'JUNTA 6'!M16+'JUNTA 7'!M16+'JUNTA 8'!M16) -> 0 | Q16: ='AREA COLECTIVA Y E.H'!D15 -> 0 | R16: ='JUNTA 1'!N16+'JUNTA 2'!N16+'JUNTA 3'!N16+'JUNTA 4'!N16+'JUNTA 5'!N16+'JUNTA 6'!N16+'JUNTA 7'!N16+'JUNTA 8'!N16+'AREA COLECTIVA Y E.H'!H15 -> 0 | S16: ='JUNTA 1'!P16+'JUNTA 2'!P16+'JUNTA 3'!P16+'JUNTA 4'!P16+'JUNTA 5'!P16+'JUNTA 6'!P16+'JUNTA 7'!P16+'JUNTA 8'!P16+'AREA COLECTIVA Y E.H'!R15 -> 0 | T16: ='JUNTA 1'!Q16+'JUNTA 2'!Q16+'JUNTA 3'!Q16+'JUNTA 4'!Q16+'JUNTA 5'!Q16+'JUNTA 6'!Q16+'JUNTA 7'!Q16+'JUNTA 8'!Q16 -> 0 | U16: ='JUNTA 1'!R16+'JUNTA 2'!R16+'JUNTA 3'!R16+'JUNTA 4'!R16+'JUNTA 5'!R16+'JUNTA 6'!R16+'JUNTA 7'!R16+'JUNTA 8'!R16+'AREA COLECTIVA Y E.H'!I15 -> 0 | V16: ='JUNTA 1'!S16+'JUNTA 2'!S16+'JUNTA 3'!S16+'JUNTA 4'!S16+'JUNTA 5'!S16+'JUNTA 6'!S16+'JUNTA 7'!S16+'JUNTA 8'!S16+'AREA COLECTIVA Y E.H'!U15 -> 0 | W16: ='JUNTA 1'!T16+'JUNTA 2'!T16+'JUNTA 3'!T16+'JUNTA 4'!T16+'JUNTA 5'!T16+'JUNTA 6'!T16+'JUNTA 7'!T16+'JUNTA 8'!T16 -> 0 | X16: ='JUNTA 1'!U16+'JUNTA 2'!U16+'JUNTA 3'!U16+'JUNTA 4'!U16+'JUNTA 5'!U16+'JUNTA 6'!U16+'JUNTA 7'!U16+'JUNTA 8'!U16 -> 0 | Y16: ='JUNTA 1'!V16+'JUNTA 2'!V16+'JUNTA 3'!V16+'JUNTA 4'!V16+'JUNTA 5'!V16+'JUNTA 6'!V16+'JUNTA 7'!V16+'JUNTA 8'!V16+'AREA COLECTIVA Y E.H'!Q15 -> 0 | Z16: ='JUNTA 1'!W16+'JUNTA 2'!W16+'JUNTA 3'!W16+'JUNTA 4'!W16+'JUNTA 5'!W16+'JUNTA 6'!W16+'JUNTA 7'!W16+'JUNTA 8'!W16+'AREA COLECTIVA Y E.H'!T15 -> 0 | AA16: ='JUNTA 1'!X16+'JUNTA 2'!X16+'JUNTA 3'!X16+'JUNTA 4'!X16+'JUNTA 5'!X16+'JUNTA 6'!X16+'JUNTA 7'!X16+'JUNTA 8'!X16 -> 0 | AB16: =SUM(B16:AA16) -> 0
A17: AGOSTO | B17: =SUM('JUNTA 1'!B17+'JUNTA 2'!B17+'JUNTA 3'!B17+'JUNTA 4'!B17+'JUNTA 5'!B17+'JUNTA 6'!B17+'JUNTA 7'!B17+'JUNTA 8'!B17) -> 0 | C17: =SUM('JUNTA 1'!C17+'JUNTA 2'!C17+'JUNTA 3'!C17+'JUNTA 4'!C17+'JUNTA 5'!C17+'JUNTA 6'!C17+'JUNTA 7'!C17+'JUNTA 8'!C17) -> 0 | D17: =SUM('JUNTA 1'!D17+'JUNTA 2'!D17+'JUNTA 3'!D17+'JUNTA 4'!D17+'JUNTA 5'!D17+'JUNTA 6'!D17+'JUNTA 7'!D17+'JUNTA 8'!D17) -> 0 | E17: =SUM('JUNTA 1'!E17+'JUNTA 2'!E17+'JUNTA 3'!E17+'JUNTA 4'!E17+'JUNTA 5'!E17+'JUNTA 6'!E17+'JUNTA 7'!E17+'JUNTA 8'!E17) -> 0 | F17: =SUM('JUNTA 1'!F17+'JUNTA 2'!F17+'JUNTA 3'!F17+'JUNTA 4'!F17+'JUNTA 5'!F17+'JUNTA 6'!F17+'JUNTA 7'!F17+'JUNTA 8'!F17) -> 0 | G17: =SUM('JUNTA 1'!G17+'JUNTA 2'!G17+'JUNTA 3'!G17+'JUNTA 4'!G17+'JUNTA 5'!G17+'JUNTA 6'!G17+'JUNTA 7'!G17+'JUNTA 8'!G17) -> 0 | H17: ='AREA COLECTIVA Y E.H'!F16 -> 0 | I17: ='JUNTA 1'!O17+'JUNTA 2'!O17+'JUNTA 3'!O17+'JUNTA 4'!O17+'JUNTA 5'!O17+'JUNTA 6'!O17+'JUNTA 7'!O17+'JUNTA 8'!O17+'AREA COLECTIVA Y E.H'!P16 -> 0 | J17: =SUM('JUNTA 1'!H17+'JUNTA 2'!H17+'JUNTA 3'!H17+'JUNTA 4'!H17+'JUNTA 5'!H17+'JUNTA 6'!H17+'JUNTA 7'!H17+'JUNTA 8'!H17) -> 0 | K17: =SUM('JUNTA 1'!I17+'JUNTA 2'!I17+'JUNTA 3'!I17+'JUNTA 4'!I17+'JUNTA 5'!I17+'JUNTA 6'!I17+'JUNTA 7'!I17+'JUNTA 8'!I17) -> 0 | L17: ='AREA COLECTIVA Y E.H'!N16 -> 0 | M17: =SUM('JUNTA 1'!J17+'JUNTA 2'!J17+'JUNTA 3'!J17+'JUNTA 4'!J17+'JUNTA 5'!J17+'JUNTA 6'!J17+'JUNTA 7'!J17+'JUNTA 8'!J17+'AREA COLECTIVA Y E.H'!E16+'AREA COLECTIVA Y E.H'!C16) -> 0 | N17: =SUM('JUNTA 1'!K17+'JUNTA 2'!K17+'JUNTA 3'!K17+'JUNTA 4'!K17+'JUNTA 5'!K17+'JUNTA 6'!K17+'JUNTA 7'!K17+'JUNTA 8'!K17) -> 0 | O17: =SUM('JUNTA 1'!L17+'JUNTA 2'!L17+'JUNTA 3'!L17+'JUNTA 4'!L17+'JUNTA 5'!L17+'JUNTA 6'!L17+'JUNTA 7'!L17+'JUNTA 8'!L17) -> 0 | P17: =SUM('JUNTA 1'!M17+'JUNTA 2'!M17+'JUNTA 3'!M17+'JUNTA 4'!M17+'JUNTA 5'!M17+'JUNTA 6'!M17+'JUNTA 7'!M17+'JUNTA 8'!M17) -> 0 | Q17: ='AREA COLECTIVA Y E.H'!D16 -> 0 | R17: ='JUNTA 1'!N17+'JUNTA 2'!N17+'JUNTA 3'!N17+'JUNTA 4'!N17+'JUNTA 5'!N17+'JUNTA 6'!N17+'JUNTA 7'!N17+'JUNTA 8'!N17+'AREA COLECTIVA Y E.H'!H16 -> 0 | S17: ='JUNTA 1'!P17+'JUNTA 2'!P17+'JUNTA 3'!P17+'JUNTA 4'!P17+'JUNTA 5'!P17+'JUNTA 6'!P17+'JUNTA 7'!P17+'JUNTA 8'!P17+'AREA COLECTIVA Y E.H'!R16 -> 0 | T17: ='JUNTA 1'!Q17+'JUNTA 2'!Q17+'JUNTA 3'!Q17+'JUNTA 4'!Q17+'JUNTA 5'!Q17+'JUNTA 6'!Q17+'JUNTA 7'!Q17+'JUNTA 8'!Q17 -> 0 | U17: ='JUNTA 1'!R17+'JUNTA 2'!R17+'JUNTA 3'!R17+'JUNTA 4'!R17+'JUNTA 5'!R17+'JUNTA 6'!R17+'JUNTA 7'!R17+'JUNTA 8'!R17+'AREA COLECTIVA Y E.H'!I16 -> 0 | V17: ='JUNTA 1'!S17+'JUNTA 2'!S17+'JUNTA 3'!S17+'JUNTA 4'!S17+'JUNTA 5'!S17+'JUNTA 6'!S17+'JUNTA 7'!S17+'JUNTA 8'!S17+'AREA COLECTIVA Y E.H'!U16 -> 0 | W17: ='JUNTA 1'!T17+'JUNTA 2'!T17+'JUNTA 3'!T17+'JUNTA 4'!T17+'JUNTA 5'!T17+'JUNTA 6'!T17+'JUNTA 7'!T17+'JUNTA 8'!T17 -> 0 | X17: ='JUNTA 1'!U17+'JUNTA 2'!U17+'JUNTA 3'!U17+'JUNTA 4'!U17+'JUNTA 5'!U17+'JUNTA 6'!U17+'JUNTA 7'!U17+'JUNTA 8'!U17 -> 0 | Y17: ='JUNTA 1'!V17+'JUNTA 2'!V17+'JUNTA 3'!V17+'JUNTA 4'!V17+'JUNTA 5'!V17+'JUNTA 6'!V17+'JUNTA 7'!V17+'JUNTA 8'!V17+'AREA COLECTIVA Y E.H'!Q16 -> 0 | Z17: ='JUNTA 1'!W17+'JUNTA 2'!W17+'JUNTA 3'!W17+'JUNTA 4'!W17+'JUNTA 5'!W17+'JUNTA 6'!W17+'JUNTA 7'!W17+'JUNTA 8'!W17+'AREA COLECTIVA Y E.H'!T16 -> 0 | AA17: ='JUNTA 1'!X17+'JUNTA 2'!X17+'JUNTA 3'!X17+'JUNTA 4'!X17+'JUNTA 5'!X17+'JUNTA 6'!X17+'JUNTA 7'!X17+'JUNTA 8'!X17 -> 0 | AB17: =SUM(B17:AA17) -> 0
A18: SEPTIEMBRE | B18: =SUM('JUNTA 1'!B18+'JUNTA 2'!B18+'JUNTA 3'!B18+'JUNTA 4'!B18+'JUNTA 5'!B18+'JUNTA 6'!B18+'JUNTA 7'!B18+'JUNTA 8'!B18) -> 0 | C18: =SUM('JUNTA 1'!C18+'JUNTA 2'!C18+'JUNTA 3'!C18+'JUNTA 4'!C18+'JUNTA 5'!C18+'JUNTA 6'!C18+'JUNTA 7'!C18+'JUNTA 8'!C18) -> 0 | D18: =SUM('JUNTA 1'!D18+'JUNTA 2'!D18+'JUNTA 3'!D18+'JUNTA 4'!D18+'JUNTA 5'!D18+'JUNTA 6'!D18+'JUNTA 7'!D18+'JUNTA 8'!D18) -> 0 | E18: =SUM('JUNTA 1'!E18+'JUNTA 2'!E18+'JUNTA 3'!E18+'JUNTA 4'!E18+'JUNTA 5'!E18+'JUNTA 6'!E18+'JUNTA 7'!E18+'JUNTA 8'!E18) -> 0 | F18: =SUM('JUNTA 1'!F18+'JUNTA 2'!F18+'JUNTA 3'!F18+'JUNTA 4'!F18+'JUNTA 5'!F18+'JUNTA 6'!F18+'JUNTA 7'!F18+'JUNTA 8'!F18) -> 0 | G18: =SUM('JUNTA 1'!G18+'JUNTA 2'!G18+'JUNTA 3'!G18+'JUNTA 4'!G18+'JUNTA 5'!G18+'JUNTA 6'!G18+'JUNTA 7'!G18+'JUNTA 8'!G18) -> 0 | H18: ='AREA COLECTIVA Y E.H'!F17 -> 0 | I18: ='JUNTA 1'!O18+'JUNTA 2'!O18+'JUNTA 3'!O18+'JUNTA 4'!O18+'JUNTA 5'!O18+'JUNTA 6'!O18+'JUNTA 7'!O18+'JUNTA 8'!O18+'AREA COLECTIVA Y E.H'!P17 -> 0 | J18: =SUM('JUNTA 1'!H18+'JUNTA 2'!H18+'JUNTA 3'!H18+'JUNTA 4'!H18+'JUNTA 5'!H18+'JUNTA 6'!H18+'JUNTA 7'!H18+'JUNTA 8'!H18) -> 0 | K18: =SUM('JUNTA 1'!I18+'JUNTA 2'!I18+'JUNTA 3'!I18+'JUNTA 4'!I18+'JUNTA 5'!I18+'JUNTA 6'!I18+'JUNTA 7'!I18+'JUNTA 8'!I18) -> 0 | L18: ='AREA COLECTIVA Y E.H'!N17 -> 0 | M18: =SUM('JUNTA 1'!J18+'JUNTA 2'!J18+'JUNTA 3'!J18+'JUNTA 4'!J18+'JUNTA 5'!J18+'JUNTA 6'!J18+'JUNTA 7'!J18+'JUNTA 8'!J18+'AREA COLECTIVA Y E.H'!E17+'AREA COLECTIVA Y E.H'!C17) -> 0 | N18: =SUM('JUNTA 1'!K18+'JUNTA 2'!K18+'JUNTA 3'!K18+'JUNTA 4'!K18+'JUNTA 5'!K18+'JUNTA 6'!K18+'JUNTA 7'!K18+'JUNTA 8'!K18) -> 0 | O18: =SUM('JUNTA 1'!L18+'JUNTA 2'!L18+'JUNTA 3'!L18+'JUNTA 4'!L18+'JUNTA 5'!L18+'JUNTA 6'!L18+'JUNTA 7'!L18+'JUNTA 8'!L18) -> 0 | P18: =SUM('JUNTA 1'!M18+'JUNTA 2'!M18+'JUNTA 3'!M18+'JUNTA 4'!M18+'JUNTA 5'!M18+'JUNTA 6'!M18+'JUNTA 7'!M18+'JUNTA 8'!M18) -> 0 | Q18: ='AREA COLECTIVA Y E.H'!D17 -> 0 | R18: ='JUNTA 1'!N18+'JUNTA 2'!N18+'JUNTA 3'!N18+'JUNTA 4'!N18+'JUNTA 5'!N18+'JUNTA 6'!N18+'JUNTA 7'!N18+'JUNTA 8'!N18+'AREA COLECTIVA Y E.H'!H17 -> 0 | S18: ='JUNTA 1'!P18+'JUNTA 2'!P18+'JUNTA 3'!P18+'JUNTA 4'!P18+'JUNTA 5'!P18+'JUNTA 6'!P18+'JUNTA 7'!P18+'JUNTA 8'!P18+'AREA COLECTIVA Y E.H'!R17 -> 0 | T18: ='JUNTA 1'!Q18+'JUNTA 2'!Q18+'JUNTA 3'!Q18+'JUNTA 4'!Q18+'JUNTA 5'!Q18+'JUNTA 6'!Q18+'JUNTA 7'!Q18+'JUNTA 8'!Q18 -> 0 | U18: ='JUNTA 1'!R18+'JUNTA 2'!R18+'JUNTA 3'!R18+'JUNTA 4'!R18+'JUNTA 5'!R18+'JUNTA 6'!R18+'JUNTA 7'!R18+'JUNTA 8'!R18+'AREA COLECTIVA Y E.H'!I17 -> 0 | V18: ='JUNTA 1'!S18+'JUNTA 2'!S18+'JUNTA 3'!S18+'JUNTA 4'!S18+'JUNTA 5'!S18+'JUNTA 6'!S18+'JUNTA 7'!S18+'JUNTA 8'!S18+'AREA COLECTIVA Y E.H'!U17 -> 0 | W18: ='JUNTA 1'!T18+'JUNTA 2'!T18+'JUNTA 3'!T18+'JUNTA 4'!T18+'JUNTA 5'!T18+'JUNTA 6'!T18+'JUNTA 7'!T18+'JUNTA 8'!T18 -> 0 | X18: ='JUNTA 1'!U18+'JUNTA 2'!U18+'JUNTA 3'!U18+'JUNTA 4'!U18+'JUNTA 5'!U18+'JUNTA 6'!U18+'JUNTA 7'!U18+'JUNTA 8'!U18 -> 0 | Y18: ='JUNTA 1'!V18+'JUNTA 2'!V18+'JUNTA 3'!V18+'JUNTA 4'!V18+'JUNTA 5'!V18+'JUNTA 6'!V18+'JUNTA 7'!V18+'JUNTA 8'!V18+'AREA COLECTIVA Y E.H'!Q17 -> 0 | Z18: ='JUNTA 1'!W18+'JUNTA 2'!W18+'JUNTA 3'!W18+'JUNTA 4'!W18+'JUNTA 5'!W18+'JUNTA 6'!W18+'JUNTA 7'!W18+'JUNTA 8'!W18+'AREA COLECTIVA Y E.H'!T17 -> 0 | AA18: ='JUNTA 1'!X18+'JUNTA 2'!X18+'JUNTA 3'!X18+'JUNTA 4'!X18+'JUNTA 5'!X18+'JUNTA 6'!X18+'JUNTA 7'!X18+'JUNTA 8'!X18 -> 0 | AB18: =SUM(B18:AA18) -> 0
A19: OCTUBRE | B19: =SUM('JUNTA 1'!B19+'JUNTA 2'!B19+'JUNTA 3'!B19+'JUNTA 4'!B19+'JUNTA 5'!B19+'JUNTA 6'!B19+'JUNTA 7'!B19+'JUNTA 8'!B19) -> 0 | C19: =SUM('JUNTA 1'!C19+'JUNTA 2'!C19+'JUNTA 3'!C19+'JUNTA 4'!C19+'JUNTA 5'!C19+'JUNTA 6'!C19+'JUNTA 7'!C19+'JUNTA 8'!C19) -> 0 | D19: =SUM('JUNTA 1'!D19+'JUNTA 2'!D19+'JUNTA 3'!D19+'JUNTA 4'!D19+'JUNTA 5'!D19+'JUNTA 6'!D19+'JUNTA 7'!D19+'JUNTA 8'!D19) -> 0 | E19: =SUM('JUNTA 1'!E19+'JUNTA 2'!E19+'JUNTA 3'!E19+'JUNTA 4'!E19+'JUNTA 5'!E19+'JUNTA 6'!E19+'JUNTA 7'!E19+'JUNTA 8'!E19) -> 0 | F19: =SUM('JUNTA 1'!F19+'JUNTA 2'!F19+'JUNTA 3'!F19+'JUNTA 4'!F19+'JUNTA 5'!F19+'JUNTA 6'!F19+'JUNTA 7'!F19+'JUNTA 8'!F19) -> 0 | G19: =SUM('JUNTA 1'!G19+'JUNTA 2'!G19+'JUNTA 3'!G19+'JUNTA 4'!G19+'JUNTA 5'!G19+'JUNTA 6'!G19+'JUNTA 7'!G19+'JUNTA 8'!G19) -> 0 | H19: ='AREA COLECTIVA Y E.H'!F18 -> 0 | I19: ='JUNTA 1'!O19+'JUNTA 2'!O19+'JUNTA 3'!O19+'JUNTA 4'!O19+'JUNTA 5'!O19+'JUNTA 6'!O19+'JUNTA 7'!O19+'JUNTA 8'!O19+'AREA COLECTIVA Y E.H'!P18 -> 0 | J19: =SUM('JUNTA 1'!H19+'JUNTA 2'!H19+'JUNTA 3'!H19+'JUNTA 4'!H19+'JUNTA 5'!H19+'JUNTA 6'!H19+'JUNTA 7'!H19+'JUNTA 8'!H19) -> 0 | K19: =SUM('JUNTA 1'!I19+'JUNTA 2'!I19+'JUNTA 3'!I19+'JUNTA 4'!I19+'JUNTA 5'!I19+'JUNTA 6'!I19+'JUNTA 7'!I19+'JUNTA 8'!I19) -> 0 | L19: ='AREA COLECTIVA Y E.H'!N18 -> 0 | M19: =SUM('JUNTA 1'!J19+'JUNTA 2'!J19+'JUNTA 3'!J19+'JUNTA 4'!J19+'JUNTA 5'!J19+'JUNTA 6'!J19+'JUNTA 7'!J19+'JUNTA 8'!J19+'AREA COLECTIVA Y E.H'!E18+'AREA COLECTIVA Y E.H'!C18) -> 0 | N19: =SUM('JUNTA 1'!K19+'JUNTA 2'!K19+'JUNTA 3'!K19+'JUNTA 4'!K19+'JUNTA 5'!K19+'JUNTA 6'!K19+'JUNTA 7'!K19+'JUNTA 8'!K19) -> 0 | O19: =SUM('JUNTA 1'!L19+'JUNTA 2'!L19+'JUNTA 3'!L19+'JUNTA 4'!L19+'JUNTA 5'!L19+'JUNTA 6'!L19+'JUNTA 7'!L19+'JUNTA 8'!L19) -> 0 | P19: =SUM('JUNTA 1'!M19+'JUNTA 2'!M19+'JUNTA 3'!M19+'JUNTA 4'!M19+'JUNTA 5'!M19+'JUNTA 6'!M19+'JUNTA 7'!M19+'JUNTA 8'!M19) -> 0 | Q19: ='AREA COLECTIVA Y E.H'!D18 -> 0 | R19: ='JUNTA 1'!N19+'JUNTA 2'!N19+'JUNTA 3'!N19+'JUNTA 4'!N19+'JUNTA 5'!N19+'JUNTA 6'!N19+'JUNTA 7'!N19+'JUNTA 8'!N19+'AREA COLECTIVA Y E.H'!H18 -> 0 | S19: ='JUNTA 1'!P19+'JUNTA 2'!P19+'JUNTA 3'!P19+'JUNTA 4'!P19+'JUNTA 5'!P19+'JUNTA 6'!P19+'JUNTA 7'!P19+'JUNTA 8'!P19+'AREA COLECTIVA Y E.H'!R18 -> 0 | T19: ='JUNTA 1'!Q19+'JUNTA 2'!Q19+'JUNTA 3'!Q19+'JUNTA 4'!Q19+'JUNTA 5'!Q19+'JUNTA 6'!Q19+'JUNTA 7'!Q19+'JUNTA 8'!Q19 -> 0 | U19: ='JUNTA 1'!R19+'JUNTA 2'!R19+'JUNTA 3'!R19+'JUNTA 4'!R19+'JUNTA 5'!R19+'JUNTA 6'!R19+'JUNTA 7'!R19+'JUNTA 8'!R19+'AREA COLECTIVA Y E.H'!I18 -> 0 | V19: ='JUNTA 1'!S19+'JUNTA 2'!S19+'JUNTA 3'!S19+'JUNTA 4'!S19+'JUNTA 5'!S19+'JUNTA 6'!S19+'JUNTA 7'!S19+'JUNTA 8'!S19+'AREA COLECTIVA Y E.H'!U18 -> 0 | W19: ='JUNTA 1'!T19+'JUNTA 2'!T19+'JUNTA 3'!T19+'JUNTA 4'!T19+'JUNTA 5'!T19+'JUNTA 6'!T19+'JUNTA 7'!T19+'JUNTA 8'!T19 -> 0 | X19: ='JUNTA 1'!U19+'JUNTA 2'!U19+'JUNTA 3'!U19+'JUNTA 4'!U19+'JUNTA 5'!U19+'JUNTA 6'!U19+'JUNTA 7'!U19+'JUNTA 8'!U19 -> 0 | Y19: ='JUNTA 1'!V19+'JUNTA 2'!V19+'JUNTA 3'!V19+'JUNTA 4'!V19+'JUNTA 5'!V19+'JUNTA 6'!V19+'JUNTA 7'!V19+'JUNTA 8'!V19+'AREA COLECTIVA Y E.H'!Q18 -> 0 | Z19: ='JUNTA 1'!W19+'JUNTA 2'!W19+'JUNTA 3'!W19+'JUNTA 4'!W19+'JUNTA 5'!W19+'JUNTA 6'!W19+'JUNTA 7'!W19+'JUNTA 8'!W19+'AREA COLECTIVA Y E.H'!T18 -> 0 | AA19: ='JUNTA 1'!X19+'JUNTA 2'!X19+'JUNTA 3'!X19+'JUNTA 4'!X19+'JUNTA 5'!X19+'JUNTA 6'!X19+'JUNTA 7'!X19+'JUNTA 8'!X19 -> 0 | AB19: =SUM(B19:AA19) -> 0
A20: NOVIEMBRE | B20: =SUM('JUNTA 1'!B20+'JUNTA 2'!B20+'JUNTA 3'!B20+'JUNTA 4'!B20+'JUNTA 5'!B20+'JUNTA 6'!B20+'JUNTA 7'!B20+'JUNTA 8'!B20) -> 0 | C20: =SUM('JUNTA 1'!C20+'JUNTA 2'!C20+'JUNTA 3'!C20+'JUNTA 4'!C20+'JUNTA 5'!C20+'JUNTA 6'!C20+'JUNTA 7'!C20+'JUNTA 8'!C20) -> 0 | D20: =SUM('JUNTA 1'!D20+'JUNTA 2'!D20+'JUNTA 3'!D20+'JUNTA 4'!D20+'JUNTA 5'!D20+'JUNTA 6'!D20+'JUNTA 7'!D20+'JUNTA 8'!D20) -> 0 | E20: =SUM('JUNTA 1'!E20+'JUNTA 2'!E20+'JUNTA 3'!E20+'JUNTA 4'!E20+'JUNTA 5'!E20+'JUNTA 6'!E20+'JUNTA 7'!E20+'JUNTA 8'!E20) -> 0 | F20: =SUM('JUNTA 1'!F20+'JUNTA 2'!F20+'JUNTA 3'!F20+'JUNTA 4'!F20+'JUNTA 5'!F20+'JUNTA 6'!F20+'JUNTA 7'!F20+'JUNTA 8'!F20) -> 0 | G20: =SUM('JUNTA 1'!G20+'JUNTA 2'!G20+'JUNTA 3'!G20+'JUNTA 4'!G20+'JUNTA 5'!G20+'JUNTA 6'!G20+'JUNTA 7'!G20+'JUNTA 8'!G20) -> 0 | H20: ='AREA COLECTIVA Y E.H'!F19 -> 0 | I20: ='JUNTA 1'!O20+'JUNTA 2'!O20+'JUNTA 3'!O20+'JUNTA 4'!O20+'JUNTA 5'!O20+'JUNTA 6'!O20+'JUNTA 7'!O20+'JUNTA 8'!O20+'AREA COLECTIVA Y E.H'!P19 -> 0 | J20: =SUM('JUNTA 1'!H20+'JUNTA 2'!H20+'JUNTA 3'!H20+'JUNTA 4'!H20+'JUNTA 5'!H20+'JUNTA 6'!H20+'JUNTA 8'!H20+'JUNTA 8'!H20) -> 0 | K20: =SUM('JUNTA 1'!I20+'JUNTA 2'!I20+'JUNTA 3'!I20+'JUNTA 4'!I20+'JUNTA 5'!I20+'JUNTA 6'!I20+'JUNTA 8'!I20+'JUNTA 8'!I20) -> 0 | L20: ='AREA COLECTIVA Y E.H'!N19 -> 0 | M20: =SUM('JUNTA 1'!J20+'JUNTA 2'!J20+'JUNTA 3'!J20+'JUNTA 4'!J20+'JUNTA 5'!J20+'JUNTA 6'!J20+'JUNTA 8'!J20+'JUNTA 8'!J20+'AREA COLECTIVA Y E.H'!E19+'AREA COLECTIVA Y E.H'!C19) -> 0 | N20: =SUM('JUNTA 1'!K20+'JUNTA 2'!K20+'JUNTA 3'!K20+'JUNTA 4'!K20+'JUNTA 5'!K20+'JUNTA 6'!K20+'JUNTA 8'!K20+'JUNTA 8'!K20) -> 0 | O20: =SUM('JUNTA 1'!L20+'JUNTA 2'!L20+'JUNTA 3'!L20+'JUNTA 4'!L20+'JUNTA 5'!L20+'JUNTA 6'!L20+'JUNTA 8'!L20+'JUNTA 8'!L20) -> 0 | P20: =SUM('JUNTA 1'!M20+'JUNTA 2'!M20+'JUNTA 3'!M20+'JUNTA 4'!M20+'JUNTA 5'!M20+'JUNTA 6'!M20+'JUNTA 8'!M20+'JUNTA 8'!M20) -> 0 | Q20: ='AREA COLECTIVA Y E.H'!D19 -> 0 | R20: ='JUNTA 1'!N20+'JUNTA 2'!N20+'JUNTA 3'!N20+'JUNTA 4'!N20+'JUNTA 5'!N20+'JUNTA 6'!N20+'JUNTA 8'!N20+'JUNTA 8'!N20+'AREA COLECTIVA Y E.H'!H19 -> 0 | S20: ='JUNTA 1'!P20+'JUNTA 2'!P20+'JUNTA 3'!P20+'JUNTA 4'!P20+'JUNTA 5'!P20+'JUNTA 6'!P20+'JUNTA 8'!P20+'JUNTA 8'!P20+'AREA COLECTIVA Y E.H'!R19 -> 0 | T20: ='JUNTA 1'!Q20+'JUNTA 2'!Q20+'JUNTA 3'!Q20+'JUNTA 4'!Q20+'JUNTA 5'!Q20+'JUNTA 6'!Q20+'JUNTA 8'!Q20+'JUNTA 8'!Q20 -> 0 | U20: ='JUNTA 1'!R20+'JUNTA 2'!R20+'JUNTA 3'!R20+'JUNTA 4'!R20+'JUNTA 5'!R20+'JUNTA 6'!R20+'JUNTA 8'!R20+'JUNTA 8'!R20+'AREA COLECTIVA Y E.H'!I19 -> 0 | V20: ='JUNTA 1'!S20+'JUNTA 2'!S20+'JUNTA 3'!S20+'JUNTA 4'!S20+'JUNTA 5'!S20+'JUNTA 6'!S20+'JUNTA 7'!S20+'JUNTA 8'!S20+'AREA COLECTIVA Y E.H'!U19 -> 0 | W20: ='JUNTA 1'!T20+'JUNTA 2'!T20+'JUNTA 3'!T20+'JUNTA 4'!T20+'JUNTA 5'!T20+'JUNTA 6'!T20+'JUNTA 8'!T20+'JUNTA 8'!T20 -> 0 | X20: ='JUNTA 1'!U20+'JUNTA 2'!U20+'JUNTA 3'!U20+'JUNTA 4'!U20+'JUNTA 5'!U20+'JUNTA 6'!U20+'JUNTA 8'!U20+'JUNTA 8'!U20 -> 0 | Y20: ='JUNTA 1'!V20+'JUNTA 2'!V20+'JUNTA 3'!V20+'JUNTA 4'!V20+'JUNTA 5'!V20+'JUNTA 6'!V20+'JUNTA 8'!V20+'JUNTA 8'!V20+'AREA COLECTIVA Y E.H'!Q19 -> 0 | Z20: ='JUNTA 1'!W20+'JUNTA 2'!W20+'JUNTA 3'!W20+'JUNTA 4'!W20+'JUNTA 5'!W20+'JUNTA 6'!W20+'JUNTA 8'!W20+'JUNTA 8'!W20+'AREA COLECTIVA Y E.H'!T18 -> 0 | AA20: ='JUNTA 1'!X20+'JUNTA 2'!X20+'JUNTA 3'!X20+'JUNTA 4'!X20+'JUNTA 5'!X20+'JUNTA 6'!X20+'JUNTA 8'!X20+'JUNTA 8'!X20 -> 0 | AB20: =SUM(B20:AA20) -> 0
A21: DICIEMBRE | B21: =SUM('JUNTA 1'!B21+'JUNTA 2'!B21+'JUNTA 3'!B21+'JUNTA 4'!B21+'JUNTA 5'!B21+'JUNTA 6'!B21+'JUNTA 7'!B21+'JUNTA 8'!B21) -> 0 | C21: =SUM('JUNTA 1'!C21+'JUNTA 2'!C21+'JUNTA 3'!C21+'JUNTA 4'!C21+'JUNTA 5'!C21+'JUNTA 6'!C21+'JUNTA 7'!C21+'JUNTA 8'!C21) -> 0 | D21: =SUM('JUNTA 1'!D21+'JUNTA 2'!D21+'JUNTA 3'!D21+'JUNTA 4'!D21+'JUNTA 5'!D21+'JUNTA 6'!D21+'JUNTA 7'!D21+'JUNTA 8'!D21) -> 0 | E21: =SUM('JUNTA 1'!E21+'JUNTA 2'!E21+'JUNTA 3'!E21+'JUNTA 4'!E21+'JUNTA 5'!E21+'JUNTA 6'!E21+'JUNTA 7'!E21+'JUNTA 8'!E21) -> 0 | F21: =SUM('JUNTA 1'!F21+'JUNTA 2'!F21+'JUNTA 3'!F21+'JUNTA 4'!F21+'JUNTA 5'!F21+'JUNTA 6'!F21+'JUNTA 7'!F21+'JUNTA 8'!F21) -> 0 | G21: =SUM('JUNTA 1'!G21+'JUNTA 2'!G21+'JUNTA 3'!G21+'JUNTA 4'!G21+'JUNTA 5'!G21+'JUNTA 6'!G21+'JUNTA 7'!G21+'JUNTA 8'!G21) -> 0 | H21: ='AREA COLECTIVA Y E.H'!F20 -> 0 | I21: ='JUNTA 1'!O21+'JUNTA 2'!O21+'JUNTA 3'!O21+'JUNTA 4'!O21+'JUNTA 5'!O21+'JUNTA 6'!O21+'JUNTA 7'!O21+'JUNTA 8'!O21+'AREA COLECTIVA Y E.H'!P20 -> 0 | J21: =SUM('JUNTA 1'!H21+'JUNTA 2'!H21+'JUNTA 3'!H21+'JUNTA 4'!H21+'JUNTA 5'!H21+'JUNTA 6'!H21+'JUNTA 7'!H21+'JUNTA 8'!H21) -> 0 | K21: =SUM('JUNTA 1'!I21+'JUNTA 2'!I21+'JUNTA 3'!I21+'JUNTA 4'!I21+'JUNTA 5'!I21+'JUNTA 6'!I21+'JUNTA 7'!I21+'JUNTA 8'!I21) -> 0 | L21: ='AREA COLECTIVA Y E.H'!N20 -> 0 | M21: =SUM('JUNTA 1'!J21+'JUNTA 2'!J21+'JUNTA 3'!J21+'JUNTA 4'!J21+'JUNTA 5'!J21+'JUNTA 6'!J21+'JUNTA 7'!J21+'JUNTA 8'!J21+'AREA COLECTIVA Y E.H'!E20+'AREA COLECTIVA Y E.H'!C20) -> 0 | N21: =SUM('JUNTA 1'!K21+'JUNTA 2'!K21+'JUNTA 3'!K21+'JUNTA 4'!K21+'JUNTA 5'!K21+'JUNTA 6'!K21+'JUNTA 7'!K21+'JUNTA 8'!K21) -> 0 | O21: =SUM('JUNTA 1'!L21+'JUNTA 2'!L21+'JUNTA 3'!L21+'JUNTA 4'!L21+'JUNTA 5'!L21+'JUNTA 6'!L21+'JUNTA 7'!L21+'JUNTA 8'!L21) -> 0 | P21: =SUM('JUNTA 1'!M21+'JUNTA 2'!M21+'JUNTA 3'!M21+'JUNTA 4'!M21+'JUNTA 5'!M21+'JUNTA 6'!M21+'JUNTA 7'!M21+'JUNTA 8'!M21) -> 0 | Q21: ='AREA COLECTIVA Y E.H'!D20 -> 0 | R21: ='JUNTA 1'!N21+'JUNTA 2'!N21+'JUNTA 3'!N21+'JUNTA 4'!N21+'JUNTA 5'!N21+'JUNTA 6'!N21+'JUNTA 7'!N21+'JUNTA 8'!N21+'AREA COLECTIVA Y E.H'!H20 -> 0 | S21: ='JUNTA 1'!P21+'JUNTA 2'!P21+'JUNTA 3'!P21+'JUNTA 4'!P21+'JUNTA 5'!P21+'JUNTA 6'!P21+'JUNTA 7'!P21+'JUNTA 8'!P21+'AREA COLECTIVA Y E.H'!R20 -> 0 | T21: ='JUNTA 1'!Q21+'JUNTA 2'!Q21+'JUNTA 3'!Q21+'JUNTA 4'!Q21+'JUNTA 5'!Q21+'JUNTA 6'!Q21+'JUNTA 7'!Q21+'JUNTA 8'!Q21 -> 0 | U21: ='JUNTA 1'!R21+'JUNTA 2'!R21+'JUNTA 3'!R21+'JUNTA 4'!R21+'JUNTA 5'!R21+'JUNTA 6'!R21+'JUNTA 7'!R21+'JUNTA 8'!R21+'AREA COLECTIVA Y E.H'!I20 -> 0 | V21: ='JUNTA 1'!S21+'JUNTA 2'!S21+'JUNTA 3'!S21+'JUNTA 4'!S21+'JUNTA 5'!S21+'JUNTA 6'!S21+'JUNTA 7'!S21+'JUNTA 8'!S21+'AREA COLECTIVA Y E.H'!U20 -> 0 | W21: ='JUNTA 1'!T21+'JUNTA 2'!T21+'JUNTA 3'!T21+'JUNTA 4'!T21+'JUNTA 5'!T21+'JUNTA 6'!T21+'JUNTA 7'!T21+'JUNTA 8'!T21 -> 0 | X21: ='JUNTA 1'!U21+'JUNTA 2'!U21+'JUNTA 3'!U21+'JUNTA 4'!U21+'JUNTA 5'!U21+'JUNTA 6'!U21+'JUNTA 7'!U21+'JUNTA 8'!U21 -> 0 | Y21: ='JUNTA 1'!V21+'JUNTA 2'!V21+'JUNTA 3'!V21+'JUNTA 4'!V21+'JUNTA 5'!V21+'JUNTA 6'!V21+'JUNTA 7'!V21+'JUNTA 8'!V21+'AREA COLECTIVA Y E.H'!Q20 -> 0 | Z21: ='JUNTA 1'!W21+'JUNTA 2'!W21+'JUNTA 3'!W21+'JUNTA 4'!W21+'JUNTA 5'!W21+'JUNTA 6'!W21+'JUNTA 7'!W21+'JUNTA 8'!W21+'AREA COLECTIVA Y E.H'!T20 -> 0 | AA21: ='JUNTA 1'!X21+'JUNTA 2'!X21+'JUNTA 3'!X21+'JUNTA 4'!X21+'JUNTA 5'!X21+'JUNTA 6'!X21+'JUNTA 7'!X21+'JUNTA 8'!X21 -> 0 | AB21: =SUM(B21:AA21) -> 0
A22: TOTAL | B22: =SUM(B10:D21) -> 2 | E22: =SUM(E10:H21) -> 428 | I22: =SUM(I10:I21) -> 54 | J22: =SUM(J10:L21) -> 8679 | M22: =SUM(M10:M21) -> 111 | N22: =SUM(N10:P21) -> 2320 | Q22: =SUM(Q10:Q21) -> 16 | R22: =SUM(R10:R21) -> 70 | S22: =SUM(S10:S21) -> 428 | T22: =SUM(T10:U21) -> 9808 | V22: =SUM(V10:V21) -> 196 | W22: =SUM(W10:X21) -> 318 | Y22: =SUM(Y10:Y21) -> 3638 | Z22: =SUM(Z10:Z21) -> 791 | AA22: =SUM(AA10:AA21) -> 217 | AB22: =SUM(AB10:AB21) -> 27076

Sheet AREA COLECTIVA Y E.H
C2: PROGRAMA PARA LA CONCLUSIÓN DE DE LOS ASUNTOS EN TRAMITE Y EJECUCIÓN DE LAUDOS EN LAS JUNTAS ESPECIALES DE LA LOCAL DE CONCILIACIÓN Y ARBITRAJE
A4: RESPONSABLE | C4: LIC. PATRICIA VELASCO VELÁZQUEZ
A5: AREA | C5: AREA COLECTIVA
A6: EJERCICIO | C6: 2025
A7: PERIODO | C7: ENERO-DICIEMBRE
A8: MES | B8: DEMANDAS | C8: CONCILIACIONES | D8: AUDIENCIAS | E8: CONVENIOS/ CONVENIOS RATIFICADOS | F8: LAUDOS | G8: EMBARGOS | H8: REMATES | I8: NOTIFICACIONES | J8: REGISTRO SINDICAL | K8: DEPÓSITO DE CONTRATOS COLECTIVOS | L8: DÉPOSITO DE REGLAMENTOS INTERIORES DE TRABAJO | M8: PROCEDIMIENTOS | N8: ACUERDOS | O8: EMPLAZAMIENTOS A HUELGA | P8: RESOLUCIONES INTERLOCUTORIAS | Q8: OFICIOS | R8: DESISTIMIENTO | S8: AMPAROS | T8: ARCHIVO | U8: EXHORTOS | V8: TOTAL
A9: ENERO | B9: 0 | C9: 0 | D9: 0 | E9: 0 | F9: 0 | G9: 0 | H9: 0 | I9: 0 | J9: 0 | K9: 0 | L9: 0 | M9: 0 | N9: 0 | O9: 0 | P9: 0 | Q9: 0 | R9: 0 | S9: 0 | T9: 0 | U9: 0 | V9: =SUM(B9:U9) -> 0
A10: FEBRERO | B10: 0 | C10: 0 | D10: 1 | E10: 0 | F10: 0 | G10: 0 | H10: 0 | I10: 58 | J10: 0 | K10: 0 | L10: 0 | M10: 0 | N10: 11 | O10: 0 | P10: 0 | Q10: 25 | R10: 0 | S10: 0 | T10: 0 | U10: 25 | V10: =SUM(B10:U10) -> 120
A11: MARZO | B11: 0 | C11: 0 | D11: 5 | E11: 1 | F11: 4 | G11: 0 | H11: 0 | I11: 114 | J11: 0 | K11: 0 | L11: 0 | M11: 0 | N11: 37 | O11: 0 | P11: 2 | Q11: 53 | R11: 0 | S11: 1 | T11: 11 | U11: 24 | V11: =SUM(B11:U11) -> 252
A12: ABRIL | D12: 10 | I12: 50 | N12: 64 | Q12: 33 | U12: 20 | V12: =SUM(B12:U12) -> 177
A13: MAYO | V13: =SUM(B13:U13) -> 0
A14: JUNIO | V14: =SUM(B14:U14) -> 0
A15: JULIO | V15: =SUM(B15:U15) -> 0
A16: AGOSTO | V16: =SUM(B16:U16) -> 0
A17: SEPTIEMBRE | V17: =SUM(B17:U17) -> 0
A18: OCTUBRE | V18: =SUM(B18:U18) -> 0
A19: NOVIEMBRE | V19: =SUM(B19:U19) -> 0
A20: DICIEMBRE | V20: =SUM(B20:U20) -> 0
A21: TOTAL | B21: =SUM(B9:B20) -> 0 | C21: =SUM(C9:C20) -> 0 | D21: =SUM(D9:D20) -> 16 | E21: =SUM(E9:E20) -> 1 | F21: =SUM(F9:F20) -> 4 | G21: =SUM(G9:G20) -> 0 | H21: =SUM(H9:H20) -> 0 | I21: =SUM(I9:I20) -> 222 | ... U21: =SUM(U9:U20) -> 69 | V21: =SUM(B21:U21) -> 549
H23: Total de procedimientos | J23: =SUM(B9:U20) -> 549 | V23: =SUM(V9:V20) -> 549

Sheet JUNTA 8
G1: JUNTA LOCAL DE CONCILIACIÓN Y ARBITRAJE
E2: PROGRAMA PARA LA CONCLUSIÓN DE DE LOS ASUNTOS EN TRAMITE Y EJECUCIÓN DE LAUDOS EN LAS JUNTAS ESPECIALES DE LA LOCAL DE CONCILIACIÓN Y ARBITRAJE
A4: RESPONSABLE | C4: LIC. LUZ CRISTINA RODRIGUEZ MARTINEZ
A5: JUNTA ESPECIAL | C5: 8
A6: EJERCICIO | C6: 2025
A7: PERIODO | C7: ENERO-DICIEMBRE
A8: MES | B8: DEMANDAS RADICADAS | E8: LAUDOS | H8: ACUERDOS | J8: CONVENIOS | K8: AUDIENCIAS | O8: RESOLUCIONES INTERLOCUTORIAS | P8: DESISTIMIENTO, CADUCIDAD E INCOMPETENCIA | Q8: NOTIFICACIONES | S8: EXHORTOS | T8: AMPAROS | V8: OFICIOS | W8: ARCHIVO | X8: DESPACHOS DE EJECUCIÓN | Y8: TOTAL ASUNTOS POR MES
B9: Ordinarias | C9: Especiales | D9: Para procesales | E9: Condenatorios | F9: Absolutorios | G9: Mixtos | H9: Junta | I9: Presidencia | J9: (cumplimentados) | K9: C,D Y E | L9: ofrecimiento | M9: desahogo de pruebas | N9: Remates e incidentales | Q9: EJECUCIONES Y DILIGENCIAS | R9: ACTUARIOS | T9: Directo | U9: Indirecto
A10: ENERO | B10: 0 | C10: 0 | D10: 0 | E10: 0 | F10: 1 | G10: 0 | H10: 37 | I10: 25 | J10: 1 | K10: 5 | L10: 3 | M10: 1 | N10: 0 | O10: 1 | P10: 1 | Q10: 3 | R10: 125 | S10: 6 | T10: 0 | U10: 0 | V10: 39 | W10: 7 | X10: 4 | Y10: =SUM(B10:X10) -> 259
A11: FEBRERO | B11: 0 | C11: 0 | D11: 0 | E11: 0 | F11: 1 | G11: 2 | H11: 81 | I11: 32 | J11: 0 | K11: 0 | L11: 5 | M11: 3 | N11: 1 | O11: 0 | P11: 0 | Q11: 0 | R11: 122 | S11: 4 | T11: 1 | U11: 0 | V11: 0 | W11: 12 | X11: 1 | Y11: =SUM(B11:X11) -> 265
A12: MARZO | B12: 0 | C12: 0 | D12: 0 | E12: 1 | F12: 0 | G12: 2 | H12: 95 | I12: 36 | J12: 0 | K12: 18 | L12: 2 | M12: 4 | N12: 1 | O12: 1 | P12: 1 | Q12: 3 | R12: 154 | S12: 18 | T12: 0 | U12: 2 | V12: 81 | W12: 16 | X12: 2 | Y12: =SUM(B12:X12) -> 437
A13: ABRIL | B13: 0 | C13: 0 | D13: 0 | E13: 1 | F13: 1 | G13: 0 | H13: 43 | I13: 144 | J13: 1 | K13: 20 | L13: 0 | M13: 3 | N13: 0 | O13: 8 | P13: 1 | Q13: 2 | R13: 154 | S13: 5 | T13: 1 | U13: 1 | V13: 0 | W13: 106 | X13: 3 | Y13: =SUM(B13:X13) -> 494
A14: MAYO | Y14: =SUM(B14:X14) -> 0
A15: JUNIO | Y15: =SUM(B15:X15) -> 0
A16: JULIO | Y16: =SUM(B16:X16) -> 0
A17: AGOSTO | Y17: =SUM(B17:X17) -> 0
A18: SEPTIEMBRE | Y18: =SUM(B18:X18) -> 0
A19: OCTUBRE | Y19: =SUM(B19:X19) -> 0
A20: NOVIEMBRE | Y20: =SUM(B20:X20) -> 0
A21: DICIEMBRE | Y21: =SUM(B21:X21) -> 0

Sheet JUNTA 7
G1: JUNTA LOCAL DE CONCILIACIÓN Y ARBITRAJE
E2: PROGRAMA PARA LA CONCLUSIÓN DE DE LOS ASUNTOS EN TRAMITE Y EJECUCIÓN DE LAUDOS EN LAS JUNTAS ESPECIALES DE LA LOCAL DE CONCILIACIÓN Y ARBITRAJE
A4: RESPONSABLE | C4: LIC. NOEL
A5: JUNTA ESPECIAL | C5: 7
A6: EJERCICIO | C6: 2025
A7: PERIODO | C7: ENERO-DICIEMBRE
A8: MES | B8: DEMANDAS RADICADAS | E8: LAUDOS | H8: ACUERDOS | J8: CONVENIOS | K8: AUDIENCIAS | O8: RESOLUCIONES INTERLOCUTORIAS | P8: DESISTIMIENTO, CADUCIDAD E INCOMPETENCIA | Q8: NOTIFICACIONES | S8: EXHORTOS | T8: AMPAROS | V8: OFICIOS | W8: ARCHIVO | X8: DESPACHOS DE EJECUCIÓN | Y8: TOTAL ASUNTOS POR MES
B9: Ordinarias | C9: Especiales | D9: Para procesales | E9: Condenatorios | F9: Absolutorios | G9: Mixtos | H9: Junta | I9: Presidencia | J9: (cumplimentados) | K9: C,D Y E | L9: ofrecimiento | M9: desahogo de pruebas | N9: Remates e incidentales | Q9: EJECUCIONES Y DILIGENCIAS | R9: ACTUARIOS | T9: Directo | U9: Indirecto
A10: ENERO | B10: 0 | C10: 0 | D10: 0 | E10: 2 | F10: 4 | G10: 0 | H10: 314 | I10: 102 | J10: 1 | K10: 88 | L10: 18 | M10: 27 | N10: 0 | O10: 1 | P10: 0 | Q10: 0 | R10: 569 | S10: 1 | T10: 2 | U10: 0 | V10: 84 | W10: 55 | X10: 7 | Y10: =SUM(B10:X10) -> 1275
A11: FEBRERO | B11: 0 | C11: 0 | D11: 0 | E11: 2 | F11: 5 | G11: 0 | H11: 411 | I11: 191 | J11: 3 | K11: 92 | L11: 19 | M11: 52 | N11: 1 | O11: 1 | P11: 44 | Q11: 3 | R11: 758 | S11: 1 | T11: 0 | U11: 0 | V11: 71 | W11: 82 | X11: 0 | Y11: =SUM(B11:X11) -> 1736
A12: MARZO | B12: 0 | C12: 0 | D12: 0 | E12: 3 | F12: 5 | G12: 0 | H12: 458 | I12: 103 | J12: 2 | K12: 88 | L12: 20 | M12: 45 | N12: 0 | O12: 0 | P12: 7 | Q12: 2 | R12: 545 | S12: 4 | T12: 1 | U12: 1 | V12: 193 | W12: 49 | X12: 13 | Y12: =SUM(B12:X12) -> 1539
A13: ABRIL | B13: 0 | C13: 0 | D13: 0 | E13: 4 | F13: 4 | G13: 0 | H13: 449 | I13: 50 | J13: 0 | K13: 148 | L13: 15 | M13: 33 | N13: 1 | O13: 0 | P13: 11 | Q13: 3 | R13: 758 | S13: 7 | T13: 0 | U13: 2 | V13: 209 | W13: 125 | X13: 5 | Y13: =SUM(B13:X13) -> 1824
A14: MAYO | Y14: =SUM(B14:X14) -> 0
A15: JUNIO | Y15: =SUM(B15:X15) -> 0
A16: JULIO | Y16: =SUM(B16:X16) -> 0
A17: AGOSTO | Y17: =SUM(B17:X17) -> 0
A18: SEPTIEMBRE | Y18: =SUM(B18:X18) -> 0
A19: OCTUBRE | Y19: =SUM(B19:X19) -> 0
A20: NOVIEMBRE | Y20: =SUM(B20:X20) -> 0
A21: DICIEMBRE | Y21: =SUM(B21:X21) -> 0

Sheet JUNTA 6
G1: JUNTA LOCAL DE CONCILIACIÓN Y ARBITRAJE
E2: PROGRAMA PARA LA CONCLUSIÓN DE DE LOS ASUNTOS EN TRAMITE Y EJECUCIÓN DE LAUDOS EN LAS JUNTAS ESPECIALES DE LA LOCAL DE CONCILIACIÓN Y ARBITRAJE
A4: RESPONSABLE | C4: LIC. RICARDO CARDENAS SANDOVAL
A5: JUNTA ESPECIAL | C5: 6 SEIS
A6: EJERCICIO | C6: 2025
A7: PERIODO | C7: ENERO-DICIEMBRE
A8: MES | B8: DEMANDAS RADICADAS | E8: LAUDOS | H8: ACUERDOS | J8: CONVENIOS | K8: AUDIENCIAS | O8: RESOLUCIONES INTERLOCUTORIAS | P8: DESISTIMIENTO, CADUCIDAD E INCOMPETENCIA | Q8: NOTIFICACIONES | S8: EXHORTOS | T8: AMPAROS | V8: OFICIOS | W8: ARCHIVO | X8: DESPACHOS DE EJECUCIÓN | Y8: TOTAL ASUNTOS POR MES
B9: Ordinarias | C9: Especiales | D9: Para procesales | E9: Condenatorios | F9: Absolutorios | G9: Mixtos | H9: Junta | I9: Presidencia | J9: (cumplimentados) | K9: C,D Y E | L9: ofrecimiento | M9: desahogo de pruebas | N9: Remates e incidentales | Q9: EJECUCIONES Y DILIGENCIAS | R9: ACTUARIOS | T9: Directo | U9: Indirecto
A10: ENERO | B10: 0 | C10: 0 | D10: 0 | E10: 13 | F10: 5 | G10: 0 | H10: 210 | I10: 86 | J10: 4 | K10: 126 | L10: 20 | M10: 49 | N10: 4 | O10: 0 | P10: 23 | Q10: 8 | R10: 312 | S10: 9 | T10: 0 | U10: 3 | V10: 97 | W10: 45 | X10: 12 | Y10: =SUM(B10:X10) -> 1026
A11: FEBRERO | B11: 0 | C11: 0 | D11: 0 | E11: 11 | F11: 7 | G11: 3 | H11: 364 | I11: 87 | J11: 11 | K11: 137 | L11: 24 | M11: 46 | N11: 5 | O11: 1 | P11: 48 | Q11: 5 | R11: 459 | S11: 11 | T11: 5 | U11: 3 | V11: 108 | W11: 69 | X11: 15 | Y11: =SUM(B11:X11) -> 1419
A12: MARZO | B12: 0 | C12: 0 | D12: 0 | E12: 10 | F12: 8 | G12: 3 | H12: 302 | I12: 77 | J12: 6 | K12: 151 | L12: 13 | M12: 59 | N12: 7 | O12: 1 | P12: 32 | Q12: 1 | R12: 370 | S12: 36 | T12: 5 | U12: 8 | V12: 134 | W12: 37 | X12: 8 | Y12: =SUM(B12:X12) -> 1268
A13: ABRIL | B13: 0 | C13: 0 | D13: 0 | E13: 16 | F13: 2 | G13: 5 | H13: 310 | I13: 154 | J13: 6 | K13: 146 | L13: 12 | M13: 60 | N13: 14 | O13: 0 | P13: 27 | Q13: 3 | R13: 603 | S13: 23 | T13: 1 | U13: 3 | V13: 114 | W13: 67 | X13: 13 | Y13: =SUM(B13:X13) -> 1579
A14: MAYO | Y14: =SUM(B14:X14) -> 0
A15: JUNIO | Y15: =SUM(B15:X15) -> 0
A16: JULIO | Y16: =SUM(B16:X16) -> 0
A17: AGOSTO | Y17: =SUM(B17:X17) -> 0
A18: SEPTIEMBRE | Y18: =SUM(B18:X18) -> 0
A19: OCTUBRE | Y19: =SUM(B19:X19) -> 0
A20: NOVIEMBRE | Y20: =SUM(B20:X20) -> 0
A21: DICIEMBRE | Y21: =SUM(B21:X21) -> 0

Sheet JUNTA 5
G1: JUNTA LOCAL DE CONCILIACIÓN Y ARBITRAJE
E2: PROGRAMA PARA LA CONCLUSIÓN DE DE LOS ASUNTOS EN TRAMITE Y EJECUCIÓN DE LAUDOS EN LAS JUNTAS ESPECIALES DE LA LOCAL DE CONCILIACIÓN Y ARBITRAJE
A4: RESPONSABLE | C4: LIC. CATALINA HERNÁNDEZ MORENO
A5: JUNTA ESPECIAL | C5: 5
A6: EJERCICIO | C6: 2025
A7: PERIODO | C7: ENERO-DICIEMBRE
A8: MES | B8: DEMANDAS RADICADAS | E8: LAUDOS | H8: ACUERDOS | J8: CONVENIOS | K8: AUDIENCIAS | O8: RESOLUCIONES INTERLOCUTORIAS | P8: DESISTIMIENTO, CADUCIDAD E INCOMPETENCIA | Q8: NOTIFICACIONES | S8: EXHORTOS | T8: AMPAROS | V8: OFICIOS | W8: ARCHIVO | X8: DESPACHOS DE EJECUCIÓN | Y8: TOTAL ASUNTOS POR MES
B9: Ordinarias | C9: Especiales | D9: Para procesales | E9: Condenatorios | F9: Absolutorios | G9: Mixtos | H9: Junta | I9: Presidencia | J9: (cumplimentados) | K9: C,D Y E | L9: ofrecimiento | M9: desahogo de pruebas | N9: Remates e incidentales | Q9: EJECUCIONES Y DILIGENCIAS | R9: ACTUARIOS | T9: Directo | U9: Indirecto
A10: ENERO | B10: 0 | C10: 0 | D10: 0 | E10: 0 | F10: 0 | G10: 0 | H10: 0 | I10: 0 | J10: 0 | K10: 0 | L10: 0 | M10: 0 | N10: 0 | O10: 0 | P10: 0 | Q10: 0 | R10: 0 | S10: 0 | T10: 0 | U10: 0 | V10: 0 | W10: 0 | X10: 0 | Y10: =SUM(B10:X10) -> 0
A11: FEBRERO | B11: 0 | C11: 0 | D11: 0 | E11: 12 | F11: 2 | G11: 3 | H11: 67 | I11: 55 | J11: 3 | K11: 0 | L11: 0 | M11: 2 | N11: 0 | O11: 8 | P11: 0 | Q11: 1 | R11: 141 | S11: 0 | T11: 8 | U11: 6 | V11: 40 | W11: 1 | X11: 5 | Y11: =SUM(B11:X11) -> 354
A12: MARZO | B12: 0 | C12: 0 | D12: 0 | E12: 11 | F12: 5 | G12: 2 | H12: 113 | I12: 81 | J12: 8 | K12: 5 | L12: 2 | M12: 8 | N12: 0 | O12: 2 | P12: 0 | Q12: 0 | R12: 260 | S12: 0 | T12: 11 | U12: 7 | V12: 70 | W12: 0 | X12: 0 | Y12: =SUM(B12:X12) -> 585
A13: ABRIL | B13: 0 | C13: 0 | D13: 0 | E13: 4 | F13: 1 | G13: 3 | H13: 176 | I13: 122 | J13: 11 | K13: 16 | L13: 0 | M13: 24 | N13: 0 | O13: 1 | P13: 0 | Q13: 3 | R13: 300 | S13: 0 | T13: 2 | U13: 12 | V13: 90 | W13: 0 | X13: 10 | Y13: =SUM(B13:X13) -> 775
A14: MAYO | Y14: =SUM(B14:X14) -> 0
A15: JUNIO | Y15: =SUM(B15:X15) -> 0
A16: JULIO | Y16: =SUM(B16:X16) -> 0
A17: AGOSTO | Y17: =SUM(B17:X17) -> 0
A18: SEPTIEMBRE | Y18: =SUM(B18:X18) -> 0
A19: OCTUBRE | Y19: =SUM(B19:X19) -> 0
A20: NOVIEMBRE | Y20: =SUM(B20:X20) -> 0
A21: DICIEMBRE | Y21: =SUM(B21:X21) -> 0

Sheet JUNTA 4
G1: JUNTA LOCAL DE CONCILIACIÓN Y ARBITRAJE
E2: PROGRAMA PARA LA CONCLUSIÓN DE DE LOS ASUNTOS EN TRAMITE Y EJECUCIÓN DE LAUDOS EN LAS JUNTAS ESPECIALES DE LA LOCAL DE CONCILIACIÓN Y ARBITRAJE
A4: RESPONSABLE | C4: LIC. MONSERRATH MARIA DE LOS ANGELES BAEZ AGUADO
A5: JUNTA ESPECIAL | C5: 4 CUATRO
A6: EJERCICIO | C6: 2025
A7: PERIODO | C7: ENERO-DICIEMBRE
A8: MES | B8: DEMANDAS RADICADAS | E8: LAUDOS | H8: ACUERDOS | J8: CONVENIOS | K8: AUDIENCIAS | O8: RESOLUCIONES INTERLOCUTORIAS | P8: DESISTIMIENTO, CADUCIDAD E INCOMPETENCIA | Q8: NOTIFICACIONES | S8: EXHORTOS | T8: AMPAROS | V8: OFICIOS | W8: ARCHIVO | X8: DESPACHOS DE EJECUCIÓN | Y8: TOTAL ASUNTOS POR MES
B9: Ordinarias | C9: Especiales | D9: Para procesales | E9: Condenatorios | F9: Absolutorios | G9: Mixtos | H9: Junta | I9: Presidencia | J9: (cumplimentados) | K9: C,D Y E | L9: ofrecimiento | M9: desahogo de pruebas | N9: Remates e incidentales | Q9: EJECUCIONES Y DILIGENCIAS | R9: ACTUARIOS | T9: Directo | U9: Indirecto
A10: ENERO | Y10: =SUM(B10:X10) -> 0
A11: FEBRERO | B11: 0 | C11: 0 | D11: 0 | E11: 7 | F11: 0 | G11: 4 | H11: 187 | I11: 92 | J11: 0 | K11: 38 | L11: 0 | M11: 0 | N11: 0 | O11: 0 | P11: 1 | Q11: 1 | R11: 119 | S11: 0 | T11: 8 | U11: 16 | V11: 38 | W11: 1 | X11: 1 | Y11: =SUM(B11:X11) -> 513
A12: MARZO | B12: 0 | C12: 0 | D12: 0 | E12: 7 | F12: 5 | G12: 9 | H12: 339 | I12: 155 | J12: 3 | K12: 28 | L12: 2 | M12: 5 | N12: 1 | O12: 2 | P12: 0 | Q12: 7 | R12: 356 | S12: 0 | T12: 8 | U12: 6 | V12: 217 | W12: 3 | X12: 7 | Y12: =SUM(B12:X12) -> 1160
A13: ABRIL | B13: 0 | C13: 0 | D13: 0 | E13: 9 | F13: 2 | G13: 10 | H13: 363 | I13: 105 | J13: 7 | K13: 29 | L13: 1 | M13: 34 | N13: 1 | O13: 2 | P13: 0 | Q13: 11 | R13: 626 | S13: 0 | T13: 12 | U13: 8 | V13: 302 | W13: 8 | X13: 12 | Y13: =SUM(B13:X13) -> 1542
A14: MAYO | Y14: =SUM(B14:X14) -> 0
A15: JUNIO | Y15: =SUM(B15:X15) -> 0
A16: JULIO | Y16: =SUM(B16:X16) -> 0
A17: AGOSTO | Y17: =SUM(B17:X17) -> 0
A18: SEPTIEMBRE | Y18: =SUM(B18:X18) -> 0
A19: OCTUBRE | Y19: =SUM(B19:X19) -> 0
A20: NOVIEMBRE | Y20: =SUM(B20:X20) -> 0
A21: DICIEMBRE | Y21: =SUM(B21:X21) -> 0

Sheet JUNTA 3
G1: JUNTA LOCAL DE CONCILIACIÓN Y ARBITRAJE
E2: PROGRAMA PARA LA CONCLUSIÓN DE DE LOS ASUNTOS EN TRAMITE Y EJECUCIÓN DE LAUDOS EN LAS JUNTAS ESPECIALES DE LA LOCAL DE CONCILIACIÓN Y ARBITRAJE
A4: RESPONSABLE | C4: LIC. ROSA EUGENIA RAMÍREZ ENRÍQUEZ
A5: JUNTA ESPECIAL | C5: 3 TRES
A6: EJERCICIO | C6: 2025
A7: PERIODO | C7: ENERO-DICIEMBRE
A8: MES | B8: DEMANDAS RADICADAS | E8: LAUDOS | H8: ACUERDOS | J8: CONVENIOS | K8: AUDIENCIAS | O8: RESOLUCIONES INTERLOCUTORIAS | P8: DESISTIMIENTO, CADUCIDAD E INCOMPETENCIA | Q8: NOTIFICACIONES | S8: EXHORTOS | T8: AMPAROS | V8: OFICIOS | W8: ARCHIVO | X8: DESPACHOS DE EJECUCIÓN | Y8: TOTAL ASUNTOS POR MES
B9: Ordinarias | C9: Especiales | D9: Para procesales | E9: Condenatorios | F9: Absolutorios | G9: Mixtos | H9: Junta | I9: Presidencia | J9: (cumplimentados) | K9: C,D Y E | L9: ofrecimiento | M9: desahogo de pruebas | N9: Remates e incidentales | Q9: EJECUCIONES Y DILIGENCIAS | R9: ACTUARIOS | T9: Directo | U9: Indirecto
A10: ENERO | B10: 0 | C10: 0 | D10: 0 | E10: 0 | F10: 0 | G10: 0 | H10: 0 | I10: 0 | J10: 0 | K10: 0 | L10: 0 | M10: 0 | N10: 0 | O10: 0 | P10: 0 | Q10: 0 | R10: 0 | S10: 0 | T10: 0 | U10: 0 | V10: 0 | W10: 0 | X10: 0 | Y10: =SUM(B10:X10) -> 0
A11: FEBRERO | B11: 0 | C11: 0 | D11: 0 | E11: 5 | F11: 6 | G11: 14 | H11: 197 | I11: 62 | J11: 1 | K11: 34 | L11: 6 | M11: 1 | N11: 2 | O11: 5 | P11: 5 | Q11: 8 | R11: 265 | S11: 1 | T11: 11 | U11: 7 | V11: 75 | W11: 4 | X11: 8 | Y11: =SUM(B11:X11) -> 717
A12: MARZO | B12: 0 | C12: 0 | D12: 0 | E12: 10 | F12: 4 | G12: 19 | H12: 309 | I12: 168 | J12: 2 | K12: 105 | L12: 11 | M12: 74 | N12: 2 | O12: 3 | P12: 31 | Q12: 22 | R12: 553 | S12: 0 | T12: 3 | U12: 13 | V12: 520 | W12: 0 | X12: 18 | Y12: =SUM(B12:X12) -> 1867
A13: ABRIL | B13: 0 | C13: 0 | D13: 0 | E13: 14 | F13: 8 | G13: 16 | H13: 358 | I13: 293 | J13: 8 | K13: 74 | L13: 13 | M13: 75 | N13: 20 | O13: 6 | P13: 15 | Q13: 30 | R13: 776 | S13: 0 | T13: 8 | U13: 4 | V13: 408 | W13: 47 | X13: 10 | Y13: =SUM(B13:X13) -> 2183
A14: MAYO | Y14: =SUM(B14:X14) -> 0
A15: JUNIO | Y15: =SUM(B15:X15) -> 0
A16: JULIO | Y16: =SUM(B16:X16) -> 0
A17: AGOSTO | Y17: =SUM(B17:X17) -> 0
A18: SEPTIEMBRE | Y18: =SUM(B18:X18) -> 0
A19: OCTUBRE | Y19: =SUM(B19:X19) -> 0
A20: NOVIEMBRE | Y20: =SUM(B20:X20) -> 0
A21: DICIEMBRE | Y21: =SUM(B21:X21) -> 0

Sheet JUNTA 2
G1: JUNTA LOCAL DE CONCILIACIÓN Y ARBITRAJE
E2: PROGRAMA PARA LA CONCLUSIÓN DE DE LOS ASUNTOS EN TRAMITE Y EJECUCIÓN DE LAUDOS EN LAS JUNTAS ESPECIALES DE LA LOCAL DE CONCILIACIÓN Y ARBITRAJE
A4: RESPONSABLE | C4: LIC. ARTURO SÁNCHEZ RÍOS
A5: JUNTA ESPECIAL | C5: 2 DOS
A6: EJERCICIO | C6: 2025
A7: PERIODO | C7: ENERO-DICIEMBRE
A8: MES | B8: DEMANDAS RADICADAS | E8: LAUDOS | H8: ACUERDOS | J8: CONVENIOS | K8: AUDIENCIAS | O8: RESOLUCIONES INTERLOCUTORIAS | P8: DESISTIMIENTO, CADUCIDAD E INCOMPETENCIA | Q8: NOTIFICACIONES | S8: EXHORTOS | T8: AMPAROS | V8: OFICIOS | W8: ARCHIVO | X8: DESPACHOS DE EJECUCIÓN | Y8: TOTAL ASUNTOS POR MES
B9: Ordinarias | C9: Especiales | D9: Para procesales | E9: Condenatorios | F9: Absolutorios | G9: Mixtos | H9: Junta | I9: Presidencia | J9: (cumplimentados) | K9: C,D Y E | L9: ofrecimiento | M9: desahogo de pruebas | N9: Remates e incidentales | Q9: EJECUCIONES Y DILIGENCIAS | R9: ACTUARIOS | T9: Directo | U9: Indirecto
A10: ENERO | B10: 0 | C10: 0 | D10: 0 | E10: 0 | F10: 0 | G10: 0 | H10: 0 | I10: 0 | J10: 0 | K10: 0 | L10: 0 | M10: 0 | N10: 0 | O10: 0 | P10: 0 | Q10: 0 | R10: 0 | S10: 0 | T10: 0 | U10: 0 | V10: 0 | W10: 0 | X10: 0 | Y10: =SUM(#REF!) -> #REF!
A11: FEBRERO | B11: 0 | C11: 0 | D11: 0 | E11: 6 | F11: 2 | G11: 4 | H11: 37 | I11: 15 | J11: 1 | K11: 0 | L11: 1 | M11: 0 | N11: 2 | O11: 0 | P11: 150 | Q11: 9 | R11: 0 | S11: 0 | T11: 0 | U11: 0 | V11: 68 | W11: 0 | X11: 2 | Y11: =SUM(#REF!) -> #REF!
A12: MARZO | B12: 0 | C12: 0 | D12: 0 | E12: 14 | F12: 7 | G12: 3 | H12: 130 | I12: 151 | J12: 6 | K12: 10 | L12: 6 | M12: 22 | N12: 4 | O12: 0 | P12: 0 | Q12: 16 | R12: 159 | S12: 1 | T12: 7 | U12: 24 | V12: 97 | W12: 0 | X12: 13 | Y12: =SUM(#REF!) -> #REF!
A13: ABRIL | B13: 0 | C13: 0 | D13: 0 | E13: 13 | F13: 6 | G13: 3 | H13: 138 | I13: 110 | J13: 22 | K13: 17 | L13: 3 | M13: 38 | N13: 1 | O13: 0 | P13: 0 | Q13: 15 | R13: 354 | S13: 0 | T13: 18 | U13: 55 | V13: 125 | W13: 0 | X13: 16 | Y13: =SUM(#REF!) -> #REF!
A14: MAYO | Y14: =SUM(#REF!) -> #REF!
A15: JUNIO | Y15: =SUM(#REF!) -> #REF!
A16: JULIO | Y16: =SUM(#REF!) -> #REF!
A17: AGOSTO | Y17: =SUM(#REF!) -> #REF!
A18: SEPTIEMBRE | Y18: =SUM(#REF!) -> #REF!
A19: OCTUBRE | Y19: =SUM(#REF!) -> #REF!
